Workbook

Sheet Hypothèses
A1: EXPORTPILOT 360 — HYPOTHÈSES DU BUSINESS PLAN
A2: Bleu = hypothèse modifiable · noir = formule · fond jaune = hypothèse clé. Montants en € HT. Aucune donnée ne provient d'un client réel : tout est hypothèse à valider sur le terrain.
A4: Scénario actif (1 = pessimiste · 2 = central · 3 = optimiste) | B4: 1
A6: 1. OFFRES ET PRIX (abonnement mensuel, engagement 12 mois)
A7: Offre « Caveau » — prix mensuel | B7: 59 | C7: WinePass : QR dégustation, fiche vins, contacts, relances FR
A8: Offre « Export » — prix mensuel | B8: 129 | C8: + réachat international, prix rendu partenaires, 4 langues, suivi
A9: Offre « Signature » — prix mensuel | B9: 249 | C9: + multi-sites, intégrations e-shop/caisse, coaching trimestriel
A10: Mix des nouveaux clients — Caveau | B10: 0.4
A11: Mix des nouveaux clients — Export | B11: 0.45
A12: Mix des nouveaux clients — Signature | B12: 0.15
A13: Prix mensuel moyen pondéré (ARPA abonnement) | B13: =Hypothèses!$B$7*Hypothèses!$B$10+Hypothèses!$B$8*Hypothèses!$B$11+Hypothèses!$B$9*Hypothèses!$B$12 -> 119
A14: Frais de mise en service (par nouveau client) | B14: 390 | C14: Paramétrage, import catalogue, formation équipe 1 h, kit QR
A15: Nombre de domaines pilotes (mise en service offerte + 3 mois gratuits) | B15: 10
A16: Mois gratuits accordés aux pilotes | B16: 3
A18: 2. REVENUS COMPLÉMENTAIRES
A19: Commission sur la valeur vin des réachats passés par la plateforme | B19: 0.02
A20: Panier vin moyen d'un réachat international (€ TTC encaissés par le domaine) | B20: 250
A21: Part des clients ayant le réachat international (Export + Signature) | B21: =Hypothèses!$B$11+Hypothèses!$B$12 -> 0.6
A22: Réachats par client éligible et par an (montée en charge du fichier) | C22: 8 | D22: 14 | E22: 18 | G22: Hypothèse prudente, à mesurer chez les pilotes
A23: Part des nouveaux clients achetant un pack DomaineDigital | B23: 0.3
A24: Prix moyen d'un pack DomaineDigital | B24: 750
A25: Coût des freelances pour les packs (en % du prix) | B25: 0.6
A27: 3. ACQUISITION ET RÉTENTION (pilotées par le scénario)
C28: Pessimiste | D28: Central | E28: Optimiste | F28: → retenu
A29: Nouveaux domaines signés — 2027 | C29: 25 | D29: 45 | E29: 65 | F29: =CHOOSE(Hypothèses!$B$4,C29,D29,E29) -> 25
A30: Nouveaux domaines signés — 2028 | C30: 80 | D30: 125 | E30: 180 | F30: =CHOOSE(Hypothèses!$B$4,C30,D30,E30) -> 80
A31: Nouveaux domaines signés — 2029 | C31: 130 | D31: 200 | E31: 290 | F31: =CHOOSE(Hypothèses!$B$4,C31,D31,E31) -> 130
A32: Churn mensuel (résiliations / clients actifs) | C32: 0.025 | D32: 0.015 | E32: 0.01 | F32: =CHOOSE(Hypothèses!$B$4,C32,D32,E32) -> 0.025
A34: 4. SAISONNALITÉ DES SIGNATURES (part annuelle signée chaque mois)
C35: janv | D35: févr | E35: mars | F35: avr | G35: mai | H35: juin | I35: juil | J35: août | K35: sept | L35: oct | M35: nov | N35: déc
A36: 2027 (MVP disponible en mars : pas de signature avant) | C36: 0 | D36: 0 | E36: 0.07 | F36: 0.11 | G36: 0.11 | H36: 0.07 | I36: 0.04 | J36: 0.02 | K36: 0.09 | L36: 0.13 | M36: 0.18 | N36: 0.18 | O36: =SUM(C36:N36) -> 1
A37: 2028-2029 (vente en basse saison caveau : nov. → avril) | C37: 0.1 | D37: 0.12 | E37: 0.14 | F37: 0.13 | G37: 0.08 | H37: 0.05 | I37: 0.03 | J37: 0.02 | K37: 0.05 | L37: 0.08 | M37: 0.1 | N37: 0.1 | O37: =SUM(C37:N37) -> 1
A39: 5. ÉQUIPE (coût employeur mensuel chargé, € — 0 = absent)
A40: Rôle | B40: Entrée (mois n°) | C40: 2027 | D40: 2028 | E40: 2029
A41: CEO — fondatrice (vente, partenariats, finance) | B41: 3 | C41: 2300 | D41: 3600 | E41: 4600
A42: CTO — cofondateur associé (produit, tech) | B42: 3 | C42: 2300 | D42: 3600 | E42: 4600
A43: Business developer terrain n°1 | B43: 11 | C43: 3900 | D43: 4000 | E43: 4100
A44: Alternant(e) marketing digital | B44: 11 | C44: 950 | D44: 950 | E44: 950
A45: Développeur(se) full-stack | B45: 99 | C45: 0 | D45: 4800 | E45: 4950
A46: Business developer terrain n°2 | B46: 99 | C46: 0 | D46: 4000 | E46: 4100
...

Sheet Mensuel
A1: MOTEUR MENSUEL — nov. 2026 → déc. 2029 (mois 1 à 38)
A3: Mois | C3: nov 26 | D3: déc 26 | E3: janv 27 | F3: févr 27 | G3: mars 27 | H3: avr 27 | I3: mai 27 | J3: juin 27 | K3: juil 27 | L3: août 27 | M3: sept 27 | N3: oct 27 | O3: nov 27 | P3: déc 27 | Q3: janv 28 | R3: févr 28 | S3: mars 28 | T3: avr 28 | U3: mai 28 | V3: juin 28 | W3: juil 28 | X3: août 28 | Y3: sept 28 | Z3: oct 28 | AA3: nov 28 | AB3: déc 28 | AC3: janv 29 | AD3: févr 29 | AE3: mars 29 | AF3: avr 29 | AG3: mai 29 | AH3: juin 29 | AI3: juil 29 | AJ3: août 29 | AK3: sept 29 | AL3: oct 29 | AM3: nov 29 | AN3: déc 29
A4: Exercice | C4: 2026 | D4: 2026 | E4: 2027 | F4: 2027 | G4: 2027 | H4: 2027 | I4: 2027 | J4: 2027 | K4: 2027 | L4: 2027 | M4: 2027 | N4: 2027 | O4: 2027 | P4: 2027 | Q4: 2028 | R4: 2028 | S4: 2028 | T4: 2028 | U4: 2028 | V4: 2028 | W4: 2028 | X4: 2028 | Y4: 2028 | Z4: 2028 | AA4: 2028 | AB4: 2028 | AC4: 2029 | AD4: 2029 | AE4: 2029 | AF4: 2029 | AG4: 2029 | AH4: 2029 | AI4: 2029 | AJ4: 2029 | AK4: 2029 | AL4: 2029 | AM4: 2029 | AN4: 2029
A6: CLIENTS
A7: Nouveaux domaines signés | C7: 0 | D7: 0 | E7: =Hypothèses!$F$29*Hypothèses!C$36 -> 0 | F7: =Hypothèses!$F$29*Hypothèses!D$36 -> 0 | G7: =Hypothèses!$F$29*Hypothèses!E$36 -> 1.75 | H7: =Hypothèses!$F$29*Hypothèses!F$36 -> 2.75 | I7: =Hypothèses!$F$29*Hypothèses!G$36 -> 2.75 | J7: =Hypothèses!$F$29*Hypothèses!H$36 -> 1.75 | K7: =Hypothèses!$F$29*Hypothèses!I$36 -> 1 | L7: =Hypothèses!$F$29*Hypothèses!J$36 -> 0.5 | ... P7: =Hypothèses!$F$29*Hypothèses!N$36 -> 4.5 | Q7: =Hypothèses!$F$30*Hypothèses!C$37 -> 8 | R7: =Hypothèses!$F$30*Hypothèses!D$37 -> 9.6 | S7: =Hypothèses!$F$30*Hypothèses!E$37 -> 11.2 | T7: =Hypothèses!$F$30*Hypothèses!F$37 -> 10.4 | U7: =Hypothèses!$F$30*Hypothèses!G$37 -> 6.4 | V7: =Hypothèses!$F$30*Hypothèses!H$37 -> 4 | W7: =Hypothèses!$F$30*Hypothèses!I$37 -> 2.4 | X7: =Hypothèses!$F$30*Hypothèses!J$37 -> 1.6 | ... AB7: =Hypothèses!$F$30*Hypothèses!N$37 -> 8 | AC7: =Hypothèses!$F$31*Hypothèses!C$37 -> 13 | AD7: =Hypothèses!$F$31*Hypothèses!D$37 -> 15.6 | AE7: =Hypothèses!$F$31*Hypothèses!E$37 -> 18.2 | AF7: =Hypothèses!$F$31*Hypothèses!F$37 -> 16.9 | AG7: =Hypothèses!$F$31*Hypothèses!G$37 -> 10.4 | AH7: =Hypothèses!$F$31*Hypothèses!H$37 -> 6.5 | AI7: =Hypothèses!$F$31*Hypothèses!I$37 -> 3.9 | AJ7: =Hypothèses!$F$31*Hypothèses!J$37 -> 2.6 | ... AN7: =Hypothèses!$F$31*Hypothèses!N$37 -> 13
A8: Cumul des signatures | C8: =0+C7 -> 0 | D8: =C8+D7 -> 0 | E8: =D8+E7 -> 0 | F8: =E8+F7 -> 0 | G8: =F8+G7 -> 1.75 | H8: =G8+H7 -> 4.5 | I8: =H8+I7 -> 7.25 | J8: =I8+J7 -> 9 | K8: =J8+K7 -> 10 | ... AN8: =AM8+AN7 -> 235
A9: Domaines actifs (fin de mois) | C9: =0*(1-Hypothèses!$F$32)+C7 -> 0 | D9: =C9*(1-Hypothèses!$F$32)+D7 -> 0 | E9: =D9*(1-Hypothèses!$F$32)+E7 -> 0 | F9: =E9*(1-Hypothèses!$F$32)+F7 -> 0 | G9: =F9*(1-Hypothèses!$F$32)+G7 -> 1.75 | H9: =G9*(1-Hypothèses!$F$32)+H7 -> 4.45625 | I9: =H9*(1-Hypothèses!$F$32)+I7 -> 7.0948437 | J9: =I9*(1-Hypothèses!$F$32)+J7 -> 8.6674727 | K9: =J9*(1-Hypothèses!$F$32)+K7 -> 9.4507858 | ... AN9: =AM9*(1-Hypothèses!$F$32)+AN7 -> 175.17527
A10: Résiliations | C10: =0*Hypothèses!$F$32 -> 0 | D10: =C9*Hypothèses!$F$32 -> 0 | E10: =D9*Hypothèses!$F$32 -> 0 | F10: =E9*Hypothèses!$F$32 -> 0 | G10: =F9*Hypothèses!$F$32 -> 0 | H10: =G9*Hypothèses!$F$32 -> 0.04375 | I10: =H9*Hypothèses!$F$32 -> 0.11140625 | J10: =I9*Hypothèses!$F$32 -> 0.17737109 | K10: =J9*Hypothèses!$F$32 -> 0.21668682 | ... AN10: =AM9*Hypothèses!$F$32 -> 4.1583403
A11: dont pilotes signés ce mois | C11: =MIN(C7,MAX(0,Hypothèses!$B$15-0)) -> 0 | D11: =MIN(D7,MAX(0,Hypothèses!$B$15-C8)) -> 0 | E11: =MIN(E7,MAX(0,Hypothèses!$B$15-D8)) -> 0 | F11: =MIN(F7,MAX(0,Hypothèses!$B$15-E8)) -> 0 | G11: =MIN(G7,MAX(0,Hypothèses!$B$15-F8)) -> 1.75 | H11: =MIN(H7,MAX(0,Hypothèses!$B$15-G8)) -> 2.75 | I11: =MIN(I7,MAX(0,Hypothèses!$B$15-H8)) -> 2.75 | J11: =MIN(J7,MAX(0,Hypothèses!$B$15-I8)) -> 1.75 | K11: =MIN(K7,MAX(0,Hypothèses!$B$15-J8)) -> 1 | ... AN11: =MIN(AN7,MAX(0,Hypothèses!$B$15-AM8)) -> 0
A12: Mises en service facturées | C12: =C7-C11 -> 0 | D12: =D7-D11 -> 0 | E12: =E7-E11 -> 0 | F12: =F7-F11 -> 0 | G12: =G7-G11 -> 0 | H12: =H7-H11 -> 0 | I12: =I7-I11 -> 0 | J12: =J7-J11 -> 0 | ... AN12: =AN7-AN11 -> 13
A13: REVENUS (€ HT)
A14: MRR — revenu mensuel récurrent (abonnements) | C14: =C9*Hypothèses!$B$13 -> 0 | D14: =D9*Hypothèses!$B$13 -> 0 | E14: =E9*Hypothèses!$B$13 -> 0 | F14: =F9*Hypothèses!$B$13 -> 0 | G14: =G9*Hypothèses!$B$13 -> 208.25 | H14: =H9*Hypothèses!$B$13 -> 530.29375 | I14: =I9*Hypothèses!$B$13 -> 844.28641 | J14: =J9*Hypothèses!$B$13 -> 1031.4292 | ... AN14: =AN9*Hypothèses!$B$13 -> 20845.857
A15: Mois offerts aux pilotes | C15: =-Hypothèses!$B$13*(C11) -> 0 | D15: =-Hypothèses!$B$13*(C11+D11) -> 0 | E15: =-Hypothèses!$B$13*(C11+D11+E11) -> 0 | F15: =-Hypothèses!$B$13*(D11+E11+F11) -> 0 | G15: =-Hypothèses!$B$13*(E11+F11+G11) -> -208.25 | H15: =-Hypothèses!$B$13*(F11+G11+H11) -> -535.5 | I15: =-Hypothèses!$B$13*(G11+H11+I11) -> -862.75 | J15: =-Hypothèses!$B$13*(H11+I11+J11) -> -862.75 | K15: =-Hypothèses!$B$13*(I11+J11+K11) -> -654.5 | L15: =-Hypothèses!$B$13*(J11+K11+L11) -> -327.25 | ... AN15: =-Hypothèses!$B$13*(AL11+AM11+AN11) -> 0
A16: CA abonnements facturé | C16: =C14+C15 -> 0 | D16: =D14+D15 -> 0 | E16: =E14+E15 -> 0 | F16: =F14+F15 -> 0 | G16: =G14+G15 -> 0 | H16: =H14+H15 -> -5.20625 | I16: =I14+I15 -> -18.463594 | J16: =J14+J15 -> 168.67925 | ... AN16: =AN14+AN15 -> 20845.857
A17: CA mises en service | C17: =C12*Hypothèses!$B$14 -> 0 | D17: =D12*Hypothèses!$B$14 -> 0 | E17: =E12*Hypothèses!$B$14 -> 0 | F17: =F12*Hypothèses!$B$14 -> 0 | G17: =G12*Hypothèses!$B$14 -> 0 | H17: =H12*Hypothèses!$B$14 -> 0 | I17: =I12*Hypothèses!$B$14 -> 0 | J17: =J12*Hypothèses!$B$14 -> 0 | ... AN17: =AN12*Hypothèses!$B$14 -> 5070
A18: CA commissions réachats | C18: 0 | D18: 0 | E18: =E9*Hypothèses!$B$21*Hypothèses!$C$22/12*Hypothèses!$B$20*Hypothèses!$B$19 -> 0 | F18: =F9*Hypothèses!$B$21*Hypothèses!$C$22/12*Hypothèses!$B$20*Hypothèses!$B$19 -> 0 | G18: =G9*Hypothèses!$B$21*Hypothèses!$C$22/12*Hypothèses!$B$20*Hypothèses!$B$19 -> 3.5 | H18: =H9*Hypothèses!$B$21*Hypothèses!$C$22/12*Hypothèses!$B$20*Hypothèses!$B$19 -> 8.9125 | I18: =I9*Hypothèses!$B$21*Hypothèses!$C$22/12*Hypothèses!$B$20*Hypothèses!$B$19 -> 14.189687 | J18: =J9*Hypothèses!$B$21*Hypothèses!$C$22/12*Hypothèses!$B$20*Hypothèses!$B$19 -> 17.334945 | K18: =K9*Hypothèses!$B$21*Hypothèses!$C$22/12*Hypothèses!$B$20*Hypothèses!$B$19 -> 18.901572 | L18: =L9*Hypothèses!$B$21*Hypothèses!$C$22/12*Hypothèses!$B$20*Hypothèses!$B$19 -> 19.429032 | ... P18: =P9*Hypothèses!$B$21*Hypothèses!$C$22/12*Hypothèses!$B$20*Hypothèses!$B$19 -> 45.682711 | Q18: =Q9*Hypothèses!$B$21*Hypothèses!$D$22/12*Hypothèses!$B$20*Hypothèses!$B$19 -> 105.94613 | R18: =R9*Hypothèses!$B$21*Hypothèses!$D$22/12*Hypothèses!$B$20*Hypothèses!$B$19 -> 136.89747 | S18: =S9*Hypothèses!$B$21*Hypothèses!$D$22/12*Hypothèses!$B$20*Hypothèses!$B$19 -> 172.67504 | T18: =T9*Hypothèses!$B$21*Hypothèses!$D$22/12*Hypothèses!$B$20*Hypothèses!$B$19 -> 204.75816 | U18: =U9*Hypothèses!$B$21*Hypothèses!$D$22/12*Hypothèses!$B$20*Hypothèses!$B$19 -> 222.03921 | V18: =V9*Hypothèses!$B$21*Hypothèses!$D$22/12*Hypothèses!$B$20*Hypothèses!$B$19 -> 230.48823 | W18: =W9*Hypothèses!$B$21*Hypothèses!$D$22/12*Hypothèses!$B$20*Hypothèses!$B$19 -> 233.12602 | X18: =X9*Hypothèses!$B$21*Hypothèses!$D$22/12*Hypothèses!$B$20*Hypothèses!$B$19 -> 232.89787 | ... AB18: =AB9*Hypothèses!$B$21*Hypothèses!$D$22/12*Hypothèses!$B$20*Hypothèses!$B$19 -> 300.03702 | AC18: =AC9*Hypothèses!$B$21*Hypothèses!$E$22/12*Hypothèses!$B$20*Hypothèses!$B$19 -> 434.61783 | AD18: =AD9*Hypothèses!$B$21*Hypothèses!$E$22/12*Hypothèses!$B$20*Hypothèses!$B$19 -> 493.95238 | AE18: =AE9*Hypothèses!$B$21*Hypothèses!$E$22/12*Hypothèses!$B$20*Hypothèses!$B$19 -> 563.50357 | AF18: =AF9*Hypothèses!$B$21*Hypothèses!$E$22/12*Hypothèses!$B$20*Hypothèses!$B$19 -> 625.46599 | AG18: =AG9*Hypothèses!$B$21*Hypothèses!$E$22/12*Hypothèses!$B$20*Hypothèses!$B$19 -> 656.62934 | AH18: =AH9*Hypothèses!$B$21*Hypothèses!$E$22/12*Hypothèses!$B$20*Hypothèses!$B$19 -> 669.4636 | AI18: =AI9*Hypothèses!$B$21*Hypothèses!$E$22/12*Hypothèses!$B$20*Hypothèses!$B$19 -> 670.27701 | AJ18: =AJ9*Hypothèses!$B$21*Hypothèses!$E$22/12*Hypothèses!$B$20*Hypothèses!$B$19 -> 665.22009 | ... AN18: =AN9*Hypothèses!$B$21*Hypothèses!$E$22/12*Hypothèses!$B$20*Hypothèses!$B$19 -> 788.28872
A19: CA packs DomaineDigital | C19: =C7*Hypothèses!$B$23*Hypothèses!$B$24 -> 0 | D19: =D7*Hypothèses!$B$23*Hypothèses!$B$24 -> 0 | E19: =E7*Hypothèses!$B$23*Hypothèses!$B$24 -> 0 | F19: =F7*Hypothèses!$B$23*Hypothèses!$B$24 -> 0 | G19: =G7*Hypothèses!$B$23*Hypothèses!$B$24 -> 393.75 | H19: =H7*Hypothèses!$B$23*Hypothèses!$B$24 -> 618.75 | I19: =I7*Hypothèses!$B$23*Hypothèses!$B$24 -> 618.75 | J19: =J7*Hypothèses!$B$23*Hypothèses!$B$24 -> 393.75 | ... AN19: =AN7*Hypothèses!$B$23*Hypothèses!$B$24 -> 2925
A20: CHIFFRE D'AFFAIRES TOTAL | C20: =SUM(C16:C19) -> 0 | D20: =SUM(D16:D19) -> 0 | E20: =SUM(E16:E19) -> 0 | F20: =SUM(F16:F19) -> 0 | G20: =SUM(G16:G19) -> 397.25 | H20: =SUM(H16:H19) -> 622.45625 | I20: =SUM(I16:I19) -> 614.47609 | J20: =SUM(J16:J19) -> 579.76419 | ... AN20: =SUM(AN16:AN19) -> 29629.146
A21: COÛTS DIRECTS
A22: Coûts variables d'infrastructure | C22: 0 | D22: 0 | E22: =E9*Hypothèses!$C$53 -> 0 | F22: =F9*Hypothèses!$C$53 -> 0 | G22: =G9*Hypothèses!$C$53 -> 8.75 | H22: =H9*Hypothèses!$C$53 -> 22.28125 | I22: =I9*Hypothèses!$C$53 -> 35.474219 | J22: =J9*Hypothèses!$C$53 -> 43.337363 | K22: =K9*Hypothèses!$C$53 -> 47.253929 | L22: =L9*Hypothèses!$C$53 -> 48.572581 | ... P22: =P9*Hypothèses!$C$53 -> 114.20678 | Q22: =Q9*Hypothèses!$D$53 -> 151.35161 | R22: =R9*Hypothèses!$D$53 -> 195.56782 | S22: =S9*Hypothèses!$D$53 -> 246.67862 | T22: =T9*Hypothèses!$D$53 -> 292.51166 | U22: =U9*Hypothèses!$D$53 -> 317.19887 | V22: =V9*Hypothèses!$D$53 -> 329.26889 | W22: =W9*Hypothèses!$D$53 -> 333.03717 | X22: =X9*Hypothèses!$D$53 -> 332.71124 | ... AB22: =AB9*Hypothèses!$D$53 -> 428.62431 | AC22: =AC9*Hypothèses!$E$53 -> 482.9087 | AD22: =AD9*Hypothèses!$E$53 -> 548.83598 | AE22: =AE9*Hypothèses!$E$53 -> 626.11508 | AF22: =AF9*Hypothèses!$E$53 -> 694.96221 | AG22: =AG9*Hypothèses!$E$53 -> 729.58815 | AH22: =AH9*Hypothèses!$E$53 -> 743.84845 | AI22: =AI9*Hypothèses!$E$53 -> 744.75224 | AJ22: =AJ9*Hypothèses!$E$53 -> 739.13343 | ... AN22: =AN9*Hypothèses!$E$53 -> 875.87636
A23: Freelances packs DomaineDigital | C23: =C19*Hypothèses!$B$25 -> 0 | D23: =D19*Hypothèses!$B$25 -> 0 | E23: =E19*Hypothèses!$B$25 -> 0 | F23: =F19*Hypothèses!$B$25 -> 0 | G23: =G19*Hypothèses!$B$25 -> 236.25 | H23: =H19*Hypothèses!$B$25 -> 371.25 | I23: =I19*Hypothèses!$B$25 -> 371.25 | J23: =J19*Hypothèses!$B$25 -> 236.25 | ... AN23: =AN19*Hypothèses!$B$25 -> 1755
A24: MARGE BRUTE | C24: =C20-C22-C23 -> 0 | D24: =D20-D22-D23 -> 0 | E24: =E20-E22-E23 -> 0 | F24: =F20-F22-F23 -> 0 | G24: =G20-G22-G23 -> 152.25 | H24: =H20-H22-H23 -> 228.925 | I24: =I20-I22-I23 -> 207.75188 | J24: =J20-J22-J23 -> 300.17683 | ... AN24: =AN20-AN22-AN23 -> 26998.27
A25: CHARGES D'EXPLOITATION
A26: Salaire chargé — CEO — fondatrice (vente, partenariats, finance) | C26: 0 | D26: 0 | E26: =IF(3>=Hypothèses!$B$41,Hypothèses!$C$41,0) -> 2300 | F26: =IF(4>=Hypothèses!$B$41,Hypothèses!$C$41,0) -> 2300 | G26: =IF(5>=Hypothèses!$B$41,Hypothèses!$C$41,0) -> 2300 | H26: =IF(6>=Hypothèses!$B$41,Hypothèses!$C$41,0) -> 2300 | I26: =IF(7>=Hypothèses!$B$41,Hypothèses!$C$41,0) -> 2300 | J26: =IF(8>=Hypothèses!$B$41,Hypothèses!$C$41,0) -> 2300 | K26: =IF(9>=Hypothèses!$B$41,Hypothèses!$C$41,0) -> 2300 | L26: =IF(10>=Hypothèses!$B$41,Hypothèses!$C$41,0) -> 2300 | M26: =IF(11>=Hypothèses!$B$41,Hypothèses!$C$41,0) -> 2300 | N26: =IF(12>=Hypothèses!$B$41,Hypothèses!$C$41,0) -> 2300 | O26: =IF(13>=Hypothèses!$B$41,Hypothèses!$C$41,0) -> 2300 | P26: =IF(14>=Hypothèses!$B$41,Hypothèses!$C$41,0) -> 2300 | Q26: =IF(15>=Hypothèses!$B$41,Hypothèses!$D$41,0) -> 3600 | R26: =IF(16>=Hypothèses!$B$41,Hypothèses!$D$41,0) -> 3600 | S26: =IF(17>=Hypothèses!$B$41,Hypothèses!$D$41,0) -> 3600 | T26: =IF(18>=Hypothèses!$B$41,Hypothèses!$D$41,0) -> 3600 | U26: =IF(19>=Hypothèses!$B$41,Hypothèses!$D$41,0) -> 3600 | V26: =IF(20>=Hypothèses!$B$41,Hypothèses!$D$41,0) -> 3600 | W26: =IF(21>=Hypothèses!$B$41,Hypothèses!$D$41,0) -> 3600 | X26: =IF(22>=Hypothèses!$B$41,Hypothèses!$D$41,0) -> 3600 | Y26: =IF(23>=Hypothèses!$B$41,Hypothèses!$D$41,0) -> 3600 | Z26: =IF(24>=Hypothèses!$B$41,Hypothèses!$D$41,0) -> 3600 | AA26: =IF(25>=Hypothèses!$B$41,Hypothèses!$D$41,0) -> 3600 | AB26: =IF(26>=Hypothèses!$B$41,Hypothèses!$D$41,0) -> 3600 | AC26: =IF(27>=Hypothèses!$B$41,Hypothèses!$E$41,0) -> 4600 | AD26: =IF(28>=Hypothèses!$B$41,Hypothèses!$E$41,0) -> 4600 | AE26: =IF(29>=Hypothèses!$B$41,Hypothèses!$E$41,0) -> 4600 | AF26: =IF(30>=Hypothèses!$B$41,Hypothèses!$E$41,0) -> 4600 | AG26: =IF(31>=Hypothèses!$B$41,Hypothèses!$E$41,0) -> 4600 | AH26: =IF(32>=Hypothèses!$B$41,Hypothèses!$E$41,0) -> 4600 | AI26: =IF(33>=Hypothèses!$B$41,Hypothèses!$E$41,0) -> 4600 | AJ26: =IF(34>=Hypothèses!$B$41,Hypothèses!$E$41,0) -> 4600 | AK26: =IF(35>=Hypothèses!$B$41,Hypothèses!$E$41,0) -> 4600 | AL26: =IF(36>=Hypothèses!$B$41,Hypothèses!$E$41,0) -> 4600 | AM26: =IF(37>=Hypothèses!$B$41,Hypothèses!$E$41,0) -> 4600 | AN26: =IF(38>=Hypothèses!$B$41,Hypothèses!$E$41,0) -> 4600
A27: Salaire chargé — CTO — cofondateur associé (produit, tech) | C27: 0 | D27: 0 | E27: =IF(3>=Hypothèses!$B$42,Hypothèses!$C$42,0) -> 2300 | F27: =IF(4>=Hypothèses!$B$42,Hypothèses!$C$42,0) -> 2300 | G27: =IF(5>=Hypothèses!$B$42,Hypothèses!$C$42,0) -> 2300 | H27: =IF(6>=Hypothèses!$B$42,Hypothèses!$C$42,0) -> 2300 | I27: =IF(7>=Hypothèses!$B$42,Hypothèses!$C$42,0) -> 2300 | J27: =IF(8>=Hypothèses!$B$42,Hypothèses!$C$42,0) -> 2300 | K27: =IF(9>=Hypothèses!$B$42,Hypothèses!$C$42,0) -> 2300 | L27: =IF(10>=Hypothèses!$B$42,Hypothèses!$C$42,0) -> 2300 | M27: =IF(11>=Hypothèses!$B$42,Hypothèses!$C$42,0) -> 2300 | N27: =IF(12>=Hypothèses!$B$42,Hypothèses!$C$42,0) -> 2300 | O27: =IF(13>=Hypothèses!$B$42,Hypothèses!$C$42,0) -> 2300 | P27: =IF(14>=Hypothèses!$B$42,Hypothèses!$C$42,0) -> 2300 | Q27: =IF(15>=Hypothèses!$B$42,Hypothèses!$D$42,0) -> 3600 | R27: =IF(16>=Hypothèses!$B$42,Hypothèses!$D$42,0) -> 3600 | S27: =IF(17>=Hypothèses!$B$42,Hypothèses!$D$42,0) -> 3600 | T27: =IF(18>=Hypothèses!$B$42,Hypothèses!$D$42,0) -> 3600 | U27: =IF(19>=Hypothèses!$B$42,Hypothèses!$D$42,0) -> 3600 | V27: =IF(20>=Hypothèses!$B$42,Hypothèses!$D$42,0) -> 3600 | W27: =IF(21>=Hypothèses!$B$42,Hypothèses!$D$42,0) -> 3600 | X27: =IF(22>=Hypothèses!$B$42,Hypothèses!$D$42,0) -> 3600 | Y27: =IF(23>=Hypothèses!$B$42,Hypothèses!$D$42,0) -> 3600 | Z27: =IF(24>=Hypothèses!$B$42,Hypothèses!$D$42,0) -> 3600 | AA27: =IF(25>=Hypothèses!$B$42,Hypothèses!$D$42,0) -> 3600 | AB27: =IF(26>=Hypothèses!$B$42,Hypothèses!$D$42,0) -> 3600 | AC27: =IF(27>=Hypothèses!$B$42,Hypothèses!$E$42,0) -> 4600 | AD27: =IF(28>=Hypothèses!$B$42,Hypothèses!$E$42,0) -> 4600 | AE27: =IF(29>=Hypothèses!$B$42,Hypothèses!$E$42,0) -> 4600 | AF27: =IF(30>=Hypothèses!$B$42,Hypothèses!$E$42,0) -> 4600 | AG27: =IF(31>=Hypothèses!$B$42,Hypothèses!$E$42,0) -> 4600 | AH27: =IF(32>=Hypothèses!$B$42,Hypothèses!$E$42,0) -> 4600 | AI27: =IF(33>=Hypothèses!$B$42,Hypothèses!$E$42,0) -> 4600 | AJ27: =IF(34>=Hypothèses!$B$42,Hypothèses!$E$42,0) -> 4600 | AK27: =IF(35>=Hypothèses!$B$42,Hypothèses!$E$42,0) -> 4600 | AL27: =IF(36>=Hypothèses!$B$42,Hypothèses!$E$42,0) -> 4600 | AM27: =IF(37>=Hypothèses!$B$42,Hypothèses!$E$42,0) -> 4600 | AN27: =IF(38>=Hypothèses!$B$42,Hypothèses!$E$42,0) -> 4600
A28: Salaire chargé — Business developer terrain n°1 | C28: 0 | D28: 0 | E28: =IF(3>=Hypothèses!$B$43,Hypothèses!$C$43,0) -> 0 | F28: =IF(4>=Hypothèses!$B$43,Hypothèses!$C$43,0) -> 0 | G28: =IF(5>=Hypothèses!$B$43,Hypothèses!$C$43,0) -> 0 | H28: =IF(6>=Hypothèses!$B$43,Hypothèses!$C$43,0) -> 0 | I28: =IF(7>=Hypothèses!$B$43,Hypothèses!$C$43,0) -> 0 | J28: =IF(8>=Hypothèses!$B$43,Hypothèses!$C$43,0) -> 0 | K28: =IF(9>=Hypothèses!$B$43,Hypothèses!$C$43,0) -> 0 | L28: =IF(10>=Hypothèses!$B$43,Hypothèses!$C$43,0) -> 0 | M28: =IF(11>=Hypothèses!$B$43,Hypothèses!$C$43,0) -> 3900 | N28: =IF(12>=Hypothèses!$B$43,Hypothèses!$C$43,0) -> 3900 | O28: =IF(13>=Hypothèses!$B$43,Hypothèses!$C$43,0) -> 3900 | P28: =IF(14>=Hypothèses!$B$43,Hypothèses!$C$43,0) -> 3900 | Q28: =IF(15>=Hypothèses!$B$43,Hypothèses!$D$43,0) -> 4000 | R28: =IF(16>=Hypothèses!$B$43,Hypothèses!$D$43,0) -> 4000 | S28: =IF(17>=Hypothèses!$B$43,Hypothèses!$D$43,0) -> 4000 | T28: =IF(18>=Hypothèses!$B$43,Hypothèses!$D$43,0) -> 4000 | U28: =IF(19>=Hypothèses!$B$43,Hypothèses!$D$43,0) -> 4000 | V28: =IF(20>=Hypothèses!$B$43,Hypothèses!$D$43,0) -> 4000 | W28: =IF(21>=Hypothèses!$B$43,Hypothèses!$D$43,0) -> 4000 | X28: =IF(22>=Hypothèses!$B$43,Hypothèses!$D$43,0) -> 4000 | Y28: =IF(23>=Hypothèses!$B$43,Hypothèses!$D$43,0) -> 4000 | Z28: =IF(24>=Hypothèses!$B$43,Hypothèses!$D$43,0) -> 4000 | AA28: =IF(25>=Hypothèses!$B$43,Hypothèses!$D$43,0) -> 4000 | AB28: =IF(26>=Hypothèses!$B$43,Hypothèses!$D$43,0) -> 4000 | AC28: =IF(27>=Hypothèses!$B$43,Hypothèses!$E$43,0) -> 4100 | AD28: =IF(28>=Hypothèses!$B$43,Hypothèses!$E$43,0) -> 4100 | AE28: =IF(29>=Hypothèses!$B$43,Hypothèses!$E$43,0) -> 4100 | AF28: =IF(30>=Hypothèses!$B$43,Hypothèses!$E$43,0) -> 4100 | AG28: =IF(31>=Hypothèses!$B$43,Hypothèses!$E$43,0) -> 4100 | AH28: =IF(32>=Hypothèses!$B$43,Hypothèses!$E$43,0) -> 4100 | AI28: =IF(33>=Hypothèses!$B$43,Hypothèses!$E$43,0) -> 4100 | AJ28: =IF(34>=Hypothèses!$B$43,Hypothèses!$E$43,0) -> 4100 | AK28: =IF(35>=Hypothèses!$B$43,Hypothèses!$E$43,0) -> 4100 | AL28: =IF(36>=Hypothèses!$B$43,Hypothèses!$E$43,0) -> 4100 | AM28: =IF(37>=Hypothèses!$B$43,Hypothèses!$E$43,0) -> 4100 | AN28: =IF(38>=Hypothèses!$B$43,Hypothèses!$E$43,0) -> 4100
A29: Salaire chargé — Alternant(e) marketing digital | C29: 0 | D29: 0 | E29: =IF(3>=Hypothèses!$B$44,Hypothèses!$C$44,0) -> 0 | F29: =IF(4>=Hypothèses!$B$44,Hypothèses!$C$44,0) -> 0 | G29: =IF(5>=Hypothèses!$B$44,Hypothèses!$C$44,0) -> 0 | H29: =IF(6>=Hypothèses!$B$44,Hypothèses!$C$44,0) -> 0 | I29: =IF(7>=Hypothèses!$B$44,Hypothèses!$C$44,0) -> 0 | J29: =IF(8>=Hypothèses!$B$44,Hypothèses!$C$44,0) -> 0 | K29: =IF(9>=Hypothèses!$B$44,Hypothèses!$C$44,0) -> 0 | L29: =IF(10>=Hypothèses!$B$44,Hypothèses!$C$44,0) -> 0 | M29: =IF(11>=Hypothèses!$B$44,Hypothèses!$C$44,0) -> 950 | N29: =IF(12>=Hypothèses!$B$44,Hypothèses!$C$44,0) -> 950 | O29: =IF(13>=Hypothèses!$B$44,Hypothèses!$C$44,0) -> 950 | P29: =IF(14>=Hypothèses!$B$44,Hypothèses!$C$44,0) -> 950 | Q29: =IF(15>=Hypothèses!$B$44,Hypothèses!$D$44,0) -> 950 | R29: =IF(16>=Hypothèses!$B$44,Hypothèses!$D$44,0) -> 950 | S29: =IF(17>=Hypothèses!$B$44,Hypothèses!$D$44,0) -> 950 | T29: =IF(18>=Hypothèses!$B$44,Hypothèses!$D$44,0) -> 950 | U29: =IF(19>=Hypothèses!$B$44,Hypothèses!$D$44,0) -> 950 | V29: =IF(20>=Hypothèses!$B$44,Hypothèses!$D$44,0) -> 950 | W29: =IF(21>=Hypothèses!$B$44,Hypothèses!$D$44,0) -> 950 | X29: =IF(22>=Hypothèses!$B$44,Hypothèses!$D$44,0) -> 950 | Y29: =IF(23>=Hypothèses!$B$44,Hypothèses!$D$44,0) -> 950 | Z29: =IF(24>=Hypothèses!$B$44,Hypothèses!$D$44,0) -> 950 | AA29: =IF(25>=Hypothèses!$B$44,Hypothèses!$D$44,0) -> 950 | AB29: =IF(26>=Hypothèses!$B$44,Hypothèses!$D$44,0) -> 950 | AC29: =IF(27>=Hypothèses!$B$44,Hypothèses!$E$44,0) -> 950 | AD29: =IF(28>=Hypothèses!$B$44,Hypothèses!$E$44,0) -> 950 | AE29: =IF(29>=Hypothèses!$B$44,Hypothèses!$E$44,0) -> 950 | AF29: =IF(30>=Hypothèses!$B$44,Hypothèses!$E$44,0) -> 950 | AG29: =IF(31>=Hypothèses!$B$44,Hypothèses!$E$44,0) -> 950 | AH29: =IF(32>=Hypothèses!$B$44,Hypothèses!$E$44,0) -> 950 | AI29: =IF(33>=Hypothèses!$B$44,Hypothèses!$E$44,0) -> 950 | AJ29: =IF(34>=Hypothèses!$B$44,Hypothèses!$E$44,0) -> 950 | AK29: =IF(35>=Hypothèses!$B$44,Hypothèses!$E$44,0) -> 950 | AL29: =IF(36>=Hypothèses!$B$44,Hypothèses!$E$44,0) -> 950 | AM29: =IF(37>=Hypothèses!$B$44,Hypothèses!$E$44,0) -> 950 | AN29: =IF(38>=Hypothèses!$B$44,Hypothèses!$E$44,0) -> 950
A30: Salaire chargé — Développeur(se) full-stack | C30: 0 | D30: 0 | E30: =IF(3>=Hypothèses!$B$45,Hypothèses!$C$45,0) -> 0 | F30: =IF(4>=Hypothèses!$B$45,Hypothèses!$C$45,0) -> 0 | G30: =IF(5>=Hypothèses!$B$45,Hypothèses!$C$45,0) -> 0 | H30: =IF(6>=Hypothèses!$B$45,Hypothèses!$C$45,0) -> 0 | I30: =IF(7>=Hypothèses!$B$45,Hypothèses!$C$45,0) -> 0 | J30: =IF(8>=Hypothèses!$B$45,Hypothèses!$C$45,0) -> 0 | K30: =IF(9>=Hypothèses!$B$45,Hypothèses!$C$45,0) -> 0 | L30: =IF(10>=Hypothèses!$B$45,Hypothèses!$C$45,0) -> 0 | M30: =IF(11>=Hypothèses!$B$45,Hypothèses!$C$45,0) -> 0 | N30: =IF(12>=Hypothèses!$B$45,Hypothèses!$C$45,0) -> 0 | O30: =IF(13>=Hypothèses!$B$45,Hypothèses!$C$45,0) -> 0 | P30: =IF(14>=Hypothèses!$B$45,Hypothèses!$C$45,0) -> 0 | Q30: =IF(15>=Hypothèses!$B$45,Hypothèses!$D$45,0) -> 0 | R30: =IF(16>=Hypothèses!$B$45,Hypothèses!$D$45,0) -> 0 | S30: =IF(17>=Hypothèses!$B$45,Hypothèses!$D$45,0) -> 0 | T30: =IF(18>=Hypothèses!$B$45,Hypothèses!$D$45,0) -> 0 | U30: =IF(19>=Hypothèses!$B$45,Hypothèses!$D$45,0) -> 0 | V30: =IF(20>=Hypothèses!$B$45,Hypothèses!$D$45,0) -> 0 | W30: =IF(21>=Hypothèses!$B$45,Hypothèses!$D$45,0) -> 0 | X30: =IF(22>=Hypothèses!$B$45,Hypothèses!$D$45,0) -> 0 | Y30: =IF(23>=Hypothèses!$B$45,Hypothèses!$D$45,0) -> 0 | Z30: =IF(24>=Hypothèses!$B$45,Hypothèses!$D$45,0) -> 0 | AA30: =IF(25>=Hypothèses!$B$45,Hypothèses!$D$45,0) -> 0 | AB30: =IF(26>=Hypothèses!$B$45,Hypothèses!$D$45,0) -> 0 | AC30: =IF(27>=Hypothèses!$B$45,Hypothèses!$E$45,0) -> 0 | AD30: =IF(28>=Hypothèses!$B$45,Hypothèses!$E$45,0) -> 0 | AE30: =IF(29>=Hypothèses!$B$45,Hypothèses!$E$45,0) -> 0 | AF30: =IF(30>=Hypothèses!$B$45,Hypothèses!$E$45,0) -> 0 | AG30: =IF(31>=Hypothèses!$B$45,Hypothèses!$E$45,0) -> 0 | AH30: =IF(32>=Hypothèses!$B$45,Hypothèses!$E$45,0) -> 0 | AI30: =IF(33>=Hypothèses!$B$45,Hypothèses!$E$45,0) -> 0 | AJ30: =IF(34>=Hypothèses!$B$45,Hypothèses!$E$45,0) -> 0 | AK30: =IF(35>=Hypothèses!$B$45,Hypothèses!$E$45,0) -> 0 | AL30: =IF(36>=Hypothèses!$B$45,Hypothèses!$E$45,0) -> 0 | AM30: =IF(37>=Hypothèses!$B$45,Hypothèses!$E$45,0) -> 0 | AN30: =IF(38>=Hypothèses!$B$45,Hypothèses!$E$45,0) -> 0
A31: Salaire chargé — Business developer terrain n°2 | C31: 0 | D31: 0 | E31: =IF(3>=Hypothèses!$B$46,Hypothèses!$C$46,0) -> 0 | F31: =IF(4>=Hypothèses!$B$46,Hypothèses!$C$46,0) -> 0 | G31: =IF(5>=Hypothèses!$B$46,Hypothèses!$C$46,0) -> 0 | H31: =IF(6>=Hypothèses!$B$46,Hypothèses!$C$46,0) -> 0 | I31: =IF(7>=Hypothèses!$B$46,Hypothèses!$C$46,0) -> 0 | J31: =IF(8>=Hypothèses!$B$46,Hypothèses!$C$46,0) -> 0 | K31: =IF(9>=Hypothèses!$B$46,Hypothèses!$C$46,0) -> 0 | L31: =IF(10>=Hypothèses!$B$46,Hypothèses!$C$46,0) -> 0 | M31: =IF(11>=Hypothèses!$B$46,Hypothèses!$C$46,0) -> 0 | N31: =IF(12>=Hypothèses!$B$46,Hypothèses!$C$46,0) -> 0 | O31: =IF(13>=Hypothèses!$B$46,Hypothèses!$C$46,0) -> 0 | P31: =IF(14>=Hypothèses!$B$46,Hypothèses!$C$46,0) -> 0 | Q31: =IF(15>=Hypothèses!$B$46,Hypothèses!$D$46,0) -> 0 | R31: =IF(16>=Hypothèses!$B$46,Hypothèses!$D$46,0) -> 0 | S31: =IF(17>=Hypothèses!$B$46,Hypothèses!$D$46,0) -> 0 | T31: =IF(18>=Hypothèses!$B$46,Hypothèses!$D$46,0) -> 0 | U31: =IF(19>=Hypothèses!$B$46,Hypothèses!$D$46,0) -> 0 | V31: =IF(20>=Hypothèses!$B$46,Hypothèses!$D$46,0) -> 0 | W31: =IF(21>=Hypothèses!$B$46,Hypothèses!$D$46,0) -> 0 | X31: =IF(22>=Hypothèses!$B$46,Hypothèses!$D$46,0) -> 0 | Y31: =IF(23>=Hypothèses!$B$46,Hypothèses!$D$46,0) -> 0 | Z31: =IF(24>=Hypothèses!$B$46,Hypothèses!$D$46,0) -> 0 | AA31: =IF(25>=Hypothèses!$B$46,Hypothèses!$D$46,0) -> 0 | AB31: =IF(26>=Hypothèses!$B$46,Hypothèses!$D$46,0) -> 0 | AC31: =IF(27>=Hypothèses!$B$46,Hypothèses!$E$46,0) -> 0 | AD31: =IF(28>=Hypothèses!$B$46,Hypothèses!$E$46,0) -> 0 | AE31: =IF(29>=Hypothèses!$B$46,Hypothèses!$E$46,0) -> 0 | AF31: =IF(30>=Hypothèses!$B$46,Hypothèses!$E$46,0) -> 0 | AG31: =IF(31>=Hypothèses!$B$46,Hypothèses!$E$46,0) -> 0 | AH31: =IF(32>=Hypothèses!$B$46,Hypothèses!$E$46,0) -> 0 | AI31: =IF(33>=Hypothèses!$B$46,Hypothèses!$E$46,0) -> 0 | AJ31: =IF(34>=Hypothèses!$B$46,Hypothèses!$E$46,0) -> 0 | AK31: =IF(35>=Hypothèses!$B$46,Hypothèses!$E$46,0) -> 0 | AL31: =IF(36>=Hypothèses!$B$46,Hypothèses!$E$46,0) -> 0 | AM31: =IF(37>=Hypothèses!$B$46,Hypothèses!$E$46,0) -> 0 | AN31: =IF(38>=Hypothèses!$B$46,Hypothèses!$E$46,0) -> 0
A32: Salaire chargé — Customer success / onboarding | C32: 0 | D32: 0 | E32: =IF(3>=Hypothèses!$B$47,Hypothèses!$C$47,0) -> 0 | F32: =IF(4>=Hypothèses!$B$47,Hypothèses!$C$47,0) -> 0 | G32: =IF(5>=Hypothèses!$B$47,Hypothèses!$C$47,0) -> 0 | H32: =IF(6>=Hypothèses!$B$47,Hypothèses!$C$47,0) -> 0 | I32: =IF(7>=Hypothèses!$B$47,Hypothèses!$C$47,0) -> 0 | J32: =IF(8>=Hypothèses!$B$47,Hypothèses!$C$47,0) -> 0 | K32: =IF(9>=Hypothèses!$B$47,Hypothèses!$C$47,0) -> 0 | L32: =IF(10>=Hypothèses!$B$47,Hypothèses!$C$47,0) -> 0 | M32: =IF(11>=Hypothèses!$B$47,Hypothèses!$C$47,0) -> 0 | N32: =IF(12>=Hypothèses!$B$47,Hypothèses!$C$47,0) -> 0 | O32: =IF(13>=Hypothèses!$B$47,Hypothèses!$C$47,0) -> 0 | P32: =IF(14>=Hypothèses!$B$47,Hypothèses!$C$47,0) -> 0 | Q32: =IF(15>=Hypothèses!$B$47,Hypothèses!$D$47,0) -> 0 | R32: =IF(16>=Hypothèses!$B$47,Hypothèses!$D$47,0) -> 0 | S32: =IF(17>=Hypothèses!$B$47,Hypothèses!$D$47,0) -> 0 | T32: =IF(18>=Hypothèses!$B$47,Hypothèses!$D$47,0) -> 0 | U32: =IF(19>=Hypothèses!$B$47,Hypothèses!$D$47,0) -> 0 | V32: =IF(20>=Hypothèses!$B$47,Hypothèses!$D$47,0) -> 0 | W32: =IF(21>=Hypothèses!$B$47,Hypothèses!$D$47,0) -> 0 | X32: =IF(22>=Hypothèses!$B$47,Hypothèses!$D$47,0) -> 0 | Y32: =IF(23>=Hypothèses!$B$47,Hypothèses!$D$47,0) -> 0 | Z32: =IF(24>=Hypothèses!$B$47,Hypothèses!$D$47,0) -> 0 | AA32: =IF(25>=Hypothèses!$B$47,Hypothèses!$D$47,0) -> 0 | AB32: =IF(26>=Hypothèses!$B$47,Hypothèses!$D$47,0) -> 0 | AC32: =IF(27>=Hypothèses!$B$47,Hypothèses!$E$47,0) -> 0 | AD32: =IF(28>=Hypothèses!$B$47,Hypothèses!$E$47,0) -> 0 | AE32: =IF(29>=Hypothèses!$B$47,Hypothèses!$E$47,0) -> 0 | AF32: =IF(30>=Hypothèses!$B$47,Hypothèses!$E$47,0) -> 0 | AG32: =IF(31>=Hypothèses!$B$47,Hypothèses!$E$47,0) -> 0 | AH32: =IF(32>=Hypothèses!$B$47,Hypothèses!$E$47,0) -> 0 | AI32: =IF(33>=Hypothèses!$B$47,Hypothèses!$E$47,0) -> 0 | AJ32: =IF(34>=Hypothèses!$B$47,Hypothèses!$E$47,0) -> 0 | AK32: =IF(35>=Hypothèses!$B$47,Hypothèses!$E$47,0) -> 0 | AL32: =IF(36>=Hypothèses!$B$47,Hypothèses!$E$47,0) -> 0 | AM32: =IF(37>=Hypothèses!$B$47,Hypothèses!$E$47,0) -> 0 | AN32: =IF(38>=Hypothèses!$B$47,Hypothèses!$E$47,0) -> 0
A33: Total salaires et charges sociales | C33: =SUM(C26:C32) -> 0 | D33: =SUM(D26:D32) -> 0 | E33: =SUM(E26:E32) -> 4600 | F33: =SUM(F26:F32) -> 4600 | G33: =SUM(G26:G32) -> 4600 | H33: =SUM(H26:H32) -> 4600 | I33: =SUM(I26:I32) -> 4600 | J33: =SUM(J26:J32) -> 4600 | ... AN33: =SUM(AN26:AN32) -> 14250
A34: Développement sous-traité (MVP puis maintenance) | C34: 0 | D34: =Hypothèses!$B$64 -> 5000 | E34: =Hypothèses!$B$64 -> 5000 | F34: =Hypothèses!$B$64 -> 5000 | G34: =Hypothèses!$B$64 -> 5000 | H34: =Hypothèses!$B$64 -> 5000 | I34: =Hypothèses!$B$65 -> 800 | J34: =Hypothèses!$B$65 -> 800 | K34: =Hypothèses!$B$65 -> 800 | L34: =Hypothèses!$B$65 -> 800 | M34: =Hypothèses!$B$65 -> 800 | N34: =Hypothèses!$B$65 -> 800 | O34: =Hypothèses!$B$65 -> 800 | P34: =Hypothèses!$B$65 -> 800 | Q34: 0 | R34: 0 | S34: 0 | T34: 0 | U34: 0 | V34: 0 | W34: 0 | X34: 0 | Y34: 0 | Z34: 0 | AA34: 0 | AB34: 0 | AC34: 0 | AD34: 0 | AE34: 0 | AF34: 0 | AG34: 0 | AH34: 0 | AI34: 0 | AJ34: 0 | AK34: 0 | AL34: 0 | AM34: 0 | AN34: 0
A35: Hébergement et licences techniques (fixe) | C35: 0 | D35: 0 | E35: =Hypothèses!$C$52 -> 250 | F35: =Hypothèses!$C$52 -> 250 | G35: =Hypothèses!$C$52 -> 250 | H35: =Hypothèses!$C$52 -> 250 | I35: =Hypothèses!$C$52 -> 250 | J35: =Hypothèses!$C$52 -> 250 | K35: =Hypothèses!$C$52 -> 250 | L35: =Hypothèses!$C$52 -> 250 | ... P35: =Hypothèses!$C$52 -> 250 | Q35: =Hypothèses!$D$52 -> 400 | R35: =Hypothèses!$D$52 -> 400 | S35: =Hypothèses!$D$52 -> 400 | T35: =Hypothèses!$D$52 -> 400 | U35: =Hypothèses!$D$52 -> 400 | V35: =Hypothèses!$D$52 -> 400 | W35: =Hypothèses!$D$52 -> 400 | X35: =Hypothèses!$D$52 -> 400 | ... AB35: =Hypothèses!$D$52 -> 400 | AC35: =Hypothèses!$E$52 -> 600 | AD35: =Hypothèses!$E$52 -> 600 | AE35: =Hypothèses!$E$52 -> 600 | AF35: =Hypothèses!$E$52 -> 600 | AG35: =Hypothèses!$E$52 -> 600 | AH35: =Hypothèses!$E$52 -> 600 | AI35: =Hypothèses!$E$52 -> 600 | AJ35: =Hypothèses!$E$52 -> 600 | ... AN35: =Hypothèses!$E$52 -> 600
A36: Marketing, salons, déplacements, primes d'apport | C36: 0 | D36: 0 | E36: =Hypothèses!$C$54+Hypothèses!$C$55+E7*Hypothèses!$B$63*Hypothèses!$B$62 -> 1000 | F36: =Hypothèses!$C$54+Hypothèses!$C$55+Hypothèses!$C$56+F7*Hypothèses!$B$63*Hypothèses!$B$62 -> 4000 | G36: =Hypothèses!$C$54+Hypothèses!$C$55+G7*Hypothèses!$B$63*Hypothèses!$B$62 -> 1052.5 | H36: =Hypothèses!$C$54+Hypothèses!$C$55+H7*Hypothèses!$B$63*Hypothèses!$B$62 -> 1082.5 | I36: =Hypothèses!$C$54+Hypothèses!$C$55+I7*Hypothèses!$B$63*Hypothèses!$B$62 -> 1082.5 | J36: =Hypothèses!$C$54+Hypothèses!$C$55+Hypothèses!$C$57+J7*Hypothèses!$B$63*Hypothèses!$B$62 -> 1052.5 | K36: =Hypothèses!$C$54+Hypothèses!$C$55+K7*Hypothèses!$B$63*Hypothèses!$B$62 -> 1030 | L36: =Hypothèses!$C$54+Hypothèses!$C$55+L7*Hypothèses!$B$63*Hypothèses!$B$62 -> 1015 | M36: =Hypothèses!$C$54+Hypothèses!$C$55+M7*Hypothèses!$B$63*Hypothèses!$B$62 -> 1067.5 | N36: =Hypothèses!$C$54+Hypothèses!$C$55+N7*Hypothèses!$B$63*Hypothèses!$B$62 -> 1097.5 | O36: =Hypothèses!$C$54+Hypothèses!$C$55+Hypothèses!$C$58+O7*Hypothèses!$B$63*Hypothèses!$B$62 -> 3135 | P36: =Hypothèses!$C$54+Hypothèses!$C$55+P7*Hypothèses!$B$63*Hypothèses!$B$62 -> 1135 | Q36: =Hypothèses!$D$54+Hypothèses!$D$55+Q7*Hypothèses!$B$63*Hypothèses!$B$62 -> 2440 | R36: =Hypothèses!$D$54+Hypothèses!$D$55+Hypothèses!$D$56+R7*Hypothèses!$B$63*Hypothèses!$B$62 -> 8488 | S36: =Hypothèses!$D$54+Hypothèses!$D$55+S7*Hypothèses!$B$63*Hypothèses!$B$62 -> 2536 | T36: =Hypothèses!$D$54+Hypothèses!$D$55+T7*Hypothèses!$B$63*Hypothèses!$B$62 -> 2512 | U36: =Hypothèses!$D$54+Hypothèses!$D$55+U7*Hypothèses!$B$63*Hypothèses!$B$62 -> 2392 | V36: =Hypothèses!$D$54+Hypothèses!$D$55+Hypothèses!$D$57+V7*Hypothèses!$B$63*Hypothèses!$B$62 -> 5320 | W36: =Hypothèses!$D$54+Hypothèses!$D$55+W7*Hypothèses!$B$63*Hypothèses!$B$62 -> 2272 | X36: =Hypothèses!$D$54+Hypothèses!$D$55+X7*Hypothèses!$B$63*Hypothèses!$B$62 -> 2248 | Y36: =Hypothèses!$D$54+Hypothèses!$D$55+Y7*Hypothèses!$B$63*Hypothèses!$B$62 -> 2320 | Z36: =Hypothèses!$D$54+Hypothèses!$D$55+Z7*Hypothèses!$B$63*Hypothèses!$B$62 -> 2392 | AA36: =Hypothèses!$D$54+Hypothèses!$D$55+Hypothèses!$D$58+AA7*Hypothèses!$B$63*Hypothèses!$B$62 -> 8440 | AB36: =Hypothèses!$D$54+Hypothèses!$D$55+AB7*Hypothèses!$B$63*Hypothèses!$B$62 -> 2440 | AC36: =Hypothèses!$E$54+Hypothèses!$E$55+AC7*Hypothèses!$B$63*Hypothèses!$B$62 -> 4090 | AD36: =Hypothèses!$E$54+Hypothèses!$E$55+Hypothèses!$E$56+AD7*Hypothèses!$B$63*Hypothèses!$B$62 -> 14168 | AE36: =Hypothèses!$E$54+Hypothèses!$E$55+AE7*Hypothèses!$B$63*Hypothèses!$B$62 -> 4246 | AF36: =Hypothèses!$E$54+Hypothèses!$E$55+AF7*Hypothèses!$B$63*Hypothèses!$B$62 -> 4207 | AG36: =Hypothèses!$E$54+Hypothèses!$E$55+AG7*Hypothèses!$B$63*Hypothèses!$B$62 -> 4012 | AH36: =Hypothèses!$E$54+Hypothèses!$E$55+Hypothèses!$E$57+AH7*Hypothèses!$B$63*Hypothèses!$B$62 -> 8895 | AI36: =Hypothèses!$E$54+Hypothèses!$E$55+AI7*Hypothèses!$B$63*Hypothèses!$B$62 -> 3817 | AJ36: =Hypothèses!$E$54+Hypothèses!$E$55+AJ7*Hypothèses!$B$63*Hypothèses!$B$62 -> 3778 | AK36: =Hypothèses!$E$54+Hypothèses!$E$55+AK7*Hypothèses!$B$63*Hypothèses!$B$62 -> 3895 | AL36: =Hypothèses!$E$54+Hypothèses!$E$55+AL7*Hypothèses!$B$63*Hypothèses!$B$62 -> 4012 | AM36: =Hypothèses!$E$54+Hypothèses!$E$55+Hypothèses!$E$58+AM7*Hypothèses!$B$63*Hypothèses!$B$62 -> 14090 | AN36: =Hypothèses!$E$54+Hypothèses!$E$55+AN7*Hypothèses!$B$63*Hypothèses!$B$62 -> 4090
A37: Frais généraux (dont ante-création) | C37: =Hypothèses!$B$66 -> 5500 | D37: =Hypothèses!$B$67 -> 2500 | E37: =Hypothèses!$C$59+Hypothèses!$C$60+Hypothèses!$C$61 -> 750 | F37: =Hypothèses!$C$59+Hypothèses!$C$60 -> 750 | G37: =Hypothèses!$C$59+Hypothèses!$C$60 -> 750 | H37: =Hypothèses!$C$59+Hypothèses!$C$60 -> 750 | I37: =Hypothèses!$C$59+Hypothèses!$C$60 -> 750 | J37: =Hypothèses!$C$59+Hypothèses!$C$60 -> 750 | K37: =Hypothèses!$C$59+Hypothèses!$C$60 -> 750 | L37: =Hypothèses!$C$59+Hypothèses!$C$60 -> 750 | M37: =Hypothèses!$C$59+Hypothèses!$C$60 -> 750 | ... P37: =Hypothèses!$C$59+Hypothèses!$C$60 -> 750 | Q37: =Hypothèses!$D$59+Hypothèses!$D$60+Hypothèses!$D$61 -> 3300 | R37: =Hypothèses!$D$59+Hypothèses!$D$60 -> 1300 | S37: =Hypothèses!$D$59+Hypothèses!$D$60 -> 1300 | T37: =Hypothèses!$D$59+Hypothèses!$D$60 -> 1300 | U37: =Hypothèses!$D$59+Hypothèses!$D$60 -> 1300 | V37: =Hypothèses!$D$59+Hypothèses!$D$60 -> 1300 | W37: =Hypothèses!$D$59+Hypothèses!$D$60 -> 1300 | X37: =Hypothèses!$D$59+Hypothèses!$D$60 -> 1300 | Y37: =Hypothèses!$D$59+Hypothèses!$D$60 -> 1300 | ... AB37: =Hypothèses!$D$59+Hypothèses!$D$60 -> 1300 | AC37: =Hypothèses!$E$59+Hypothèses!$E$60+Hypothèses!$E$61 -> 4500 | AD37: =Hypothèses!$E$59+Hypothèses!$E$60 -> 2000 | AE37: =Hypothèses!$E$59+Hypothèses!$E$60 -> 2000 | AF37: =Hypothèses!$E$59+Hypothèses!$E$60 -> 2000 | AG37: =Hypothèses!$E$59+Hypothèses!$E$60 -> 2000 | AH37: =Hypothèses!$E$59+Hypothèses!$E$60 -> 2000 | AI37: =Hypothèses!$E$59+Hypothèses!$E$60 -> 2000 | AJ37: =Hypothèses!$E$59+Hypothèses!$E$60 -> 2000 | AK37: =Hypothèses!$E$59+Hypothèses!$E$60 -> 2000 | ... AN37: =Hypothèses!$E$59+Hypothèses!$E$60 -> 2000
A38: TOTAL CHARGES D'EXPLOITATION | C38: =C33+C34+C35+C36+C37 -> 5500 | D38: =D33+D34+D35+D36+D37 -> 7500 | E38: =E33+E34+E35+E36+E37 -> 11600 | F38: =F33+F34+F35+F36+F37 -> 14600 | G38: =G33+G34+G35+G36+G37 -> 11652.5 | H38: =H33+H34+H35+H36+H37 -> 11682.5 | I38: =I33+I34+I35+I36+I37 -> 7482.5 | J38: =J33+J34+J35+J36+J37 -> 7452.5 | ... AN38: =AN33+AN34+AN35+AN36+AN37 -> 20940
A39: EBE (EBITDA) | C39: =C24-C38 -> -5500 | D39: =D24-D38 -> -7500 | E39: =E24-E38 -> -11600 | F39: =F24-F38 -> -14600 | G39: =G24-G38 -> -11500.25 | H39: =H24-H38 -> -11453.575 | I39: =I24-I38 -> -7274.7481 | J39: =J24-J38 -> -7152.3232 | ... AN39: =AN24-AN38 -> 6058.2697
A40: EBE glissant 3 mois (repère du point mort) | C40: =SUM(C39:C39) -> -5500 | D40: =SUM(C39:D39) -> -13000 | E40: =SUM(C39:E39) -> -24600 | F40: =SUM(D39:F39) -> -33700 | G40: =SUM(E39:G39) -> -37700.25 | H40: =SUM(F39:H39) -> -37553.825 | I40: =SUM(G39:I39) -> -30228.573 | J40: =SUM(H39:J39) -> -25880.646 | K40: =SUM(I39:K39) -> -21325.28 | L40: =SUM(J39:L39) -> -20425.898 | ... AN40: =SUM(AL39:AN39) -> 3834.7341
A41: Point mort atteint (EBE glissant 3 mois > 0 et le reste) | C41: =IF(COUNTIF(C40:$AN$40,"<=0")=0,1,0) -> 0 | D41: =IF(COUNTIF(D40:$AN$40,"<=0")=0,1,0) -> 0 | E41: =IF(COUNTIF(E40:$AN$40,"<=0")=0,1,0) -> 0 | F41: =IF(COUNTIF(F40:$AN$40,"<=0")=0,1,0) -> 0 | G41: =IF(COUNTIF(G40:$AN$40,"<=0")=0,1,0) -> 0 | H41: =IF(COUNTIF(H40:$AN$40,"<=0")=0,1,0) -> 0 | I41: =IF(COUNTIF(I40:$AN$40,"<=0")=0,1,0) -> 0 | J41: =IF(COUNTIF(J40:$AN$40,"<=0")=0,1,0) -> 0 | ... AN41: =IF(COUNTIF(AN40:$AN$40,"<=0")=0,1,0) -> 1
A42: INVESTISSEMENTS ET AMORTISSEMENTS
...

Sheet Synthèse
A1: SYNTHÈSE — compte de résultat, plan de financement, KPI, seuil de rentabilité
A4: COMPTE DE RÉSULTAT (€ HT) | B4: Ante-création (nov.-déc. 26) | C4: 2027 | D4: 2028 | E4: 2029
A5: CA abonnements | B5: =SUMIF(Mensuel!$C$4:$AN$4,2026,Mensuel!$C$16:$AN$16) -> 0 | C5: =SUMIF(Mensuel!$C$4:$AN$4,2027,Mensuel!$C$16:$AN$16) -> 9423.2692 | D5: =SUMIF(Mensuel!$C$4:$AN$4,2028,Mensuel!$C$16:$AN$16) -> 88957.648 | E5: =SUMIF(Mensuel!$C$4:$AN$4,2029,Mensuel!$C$16:$AN$16) -> 203660.65
A6: CA mises en service | B6: =SUMIF(Mensuel!$C$4:$AN$4,2026,Mensuel!$C$17:$AN$17) -> 0 | C6: =SUMIF(Mensuel!$C$4:$AN$4,2027,Mensuel!$C$17:$AN$17) -> 5850 | D6: =SUMIF(Mensuel!$C$4:$AN$4,2028,Mensuel!$C$17:$AN$17) -> 31200 | E6: =SUMIF(Mensuel!$C$4:$AN$4,2029,Mensuel!$C$17:$AN$17) -> 50700
A7: CA commissions réachats | B7: =SUMIF(Mensuel!$C$4:$AN$4,2026,Mensuel!$C$18:$AN$18) -> 0 | C7: =SUMIF(Mensuel!$C$4:$AN$4,2027,Mensuel!$C$18:$AN$18) -> 218.37427 | D7: =SUMIF(Mensuel!$C$4:$AN$4,2028,Mensuel!$C$18:$AN$18) -> 2616.4014 | E7: =SUMIF(Mensuel!$C$4:$AN$4,2029,Mensuel!$C$18:$AN$18) -> 7701.453
A8: CA packs DomaineDigital | B8: =SUMIF(Mensuel!$C$4:$AN$4,2026,Mensuel!$C$19:$AN$19) -> 0 | C8: =SUMIF(Mensuel!$C$4:$AN$4,2027,Mensuel!$C$19:$AN$19) -> 5625 | D8: =SUMIF(Mensuel!$C$4:$AN$4,2028,Mensuel!$C$19:$AN$19) -> 18000 | E8: =SUMIF(Mensuel!$C$4:$AN$4,2029,Mensuel!$C$19:$AN$19) -> 29250
A9: Chiffre d'affaires total | B9: =SUMIF(Mensuel!$C$4:$AN$4,2026,Mensuel!$C$20:$AN$20) -> 0 | C9: =SUMIF(Mensuel!$C$4:$AN$4,2027,Mensuel!$C$20:$AN$20) -> 21116.643 | D9: =SUMIF(Mensuel!$C$4:$AN$4,2028,Mensuel!$C$20:$AN$20) -> 140774.05 | E9: =SUMIF(Mensuel!$C$4:$AN$4,2029,Mensuel!$C$20:$AN$20) -> 291312.1
A10: Coûts directs (infrastructure variable + freelances) | B10: =SUMIF(Mensuel!$C$4:$AN$4,2026,Mensuel!$C$22:$AN$22)+SUMIF(Mensuel!$C$4:$AN$4,2026,Mensuel!$C$23:$AN$23) -> 0 | C10: =SUMIF(Mensuel!$C$4:$AN$4,2027,Mensuel!$C$22:$AN$22)+SUMIF(Mensuel!$C$4:$AN$4,2027,Mensuel!$C$23:$AN$23) -> 3920.9357 | D10: =SUMIF(Mensuel!$C$4:$AN$4,2028,Mensuel!$C$22:$AN$22)+SUMIF(Mensuel!$C$4:$AN$4,2028,Mensuel!$C$23:$AN$23) -> 14537.716 | E10: =SUMIF(Mensuel!$C$4:$AN$4,2029,Mensuel!$C$22:$AN$22)+SUMIF(Mensuel!$C$4:$AN$4,2029,Mensuel!$C$23:$AN$23) -> 26107.17
A11: Marge brute | B11: =SUMIF(Mensuel!$C$4:$AN$4,2026,Mensuel!$C$24:$AN$24) -> 0 | C11: =SUMIF(Mensuel!$C$4:$AN$4,2027,Mensuel!$C$24:$AN$24) -> 17195.708 | D11: =SUMIF(Mensuel!$C$4:$AN$4,2028,Mensuel!$C$24:$AN$24) -> 126236.33 | E11: =SUMIF(Mensuel!$C$4:$AN$4,2029,Mensuel!$C$24:$AN$24) -> 265204.93
A12: Taux de marge brute | B12: =IF(B9=0,0,B11/B9) -> 0 | C12: =IF(C9=0,0,C11/C9) -> 0.81432013 | D12: =IF(D9=0,0,D11/D9) -> 0.89673014 | E12: =IF(E9=0,0,E11/E9) -> 0.91038076
A13: Salaires et charges sociales | B13: =SUMIF(Mensuel!$C$4:$AN$4,2026,Mensuel!$C$33:$AN$33) -> 0 | C13: =SUMIF(Mensuel!$C$4:$AN$4,2027,Mensuel!$C$33:$AN$33) -> 74600 | D13: =SUMIF(Mensuel!$C$4:$AN$4,2028,Mensuel!$C$33:$AN$33) -> 145800 | E13: =SUMIF(Mensuel!$C$4:$AN$4,2029,Mensuel!$C$33:$AN$33) -> 171000
A14: Développement sous-traité + hébergement | B14: =SUMIF(Mensuel!$C$4:$AN$4,2026,Mensuel!$C$34:$AN$34)+SUMIF(Mensuel!$C$4:$AN$4,2026,Mensuel!$C$35:$AN$35) -> 5000 | C14: =SUMIF(Mensuel!$C$4:$AN$4,2027,Mensuel!$C$34:$AN$34)+SUMIF(Mensuel!$C$4:$AN$4,2027,Mensuel!$C$35:$AN$35) -> 29400 | D14: =SUMIF(Mensuel!$C$4:$AN$4,2028,Mensuel!$C$34:$AN$34)+SUMIF(Mensuel!$C$4:$AN$4,2028,Mensuel!$C$35:$AN$35) -> 4800 | E14: =SUMIF(Mensuel!$C$4:$AN$4,2029,Mensuel!$C$34:$AN$34)+SUMIF(Mensuel!$C$4:$AN$4,2029,Mensuel!$C$35:$AN$35) -> 7200
A15: Marketing, salons, déplacements | B15: =SUMIF(Mensuel!$C$4:$AN$4,2026,Mensuel!$C$36:$AN$36) -> 0 | C15: =SUMIF(Mensuel!$C$4:$AN$4,2027,Mensuel!$C$36:$AN$36) -> 17750 | D15: =SUMIF(Mensuel!$C$4:$AN$4,2028,Mensuel!$C$36:$AN$36) -> 43800 | E15: =SUMIF(Mensuel!$C$4:$AN$4,2029,Mensuel!$C$36:$AN$36) -> 73300
A16: Frais généraux | B16: =SUMIF(Mensuel!$C$4:$AN$4,2026,Mensuel!$C$37:$AN$37) -> 8000 | C16: =SUMIF(Mensuel!$C$4:$AN$4,2027,Mensuel!$C$37:$AN$37) -> 9000 | D16: =SUMIF(Mensuel!$C$4:$AN$4,2028,Mensuel!$C$37:$AN$37) -> 17600 | E16: =SUMIF(Mensuel!$C$4:$AN$4,2029,Mensuel!$C$37:$AN$37) -> 26500
A17: EBE (EBITDA) | B17: =SUMIF(Mensuel!$C$4:$AN$4,2026,Mensuel!$C$39:$AN$39) -> -13000 | C17: =SUMIF(Mensuel!$C$4:$AN$4,2027,Mensuel!$C$39:$AN$39) -> -113554.29 | D17: =SUMIF(Mensuel!$C$4:$AN$4,2028,Mensuel!$C$39:$AN$39) -> -85763.667 | E17: =SUMIF(Mensuel!$C$4:$AN$4,2029,Mensuel!$C$39:$AN$39) -> -12795.072
A18: Amortissements | B18: =SUMIF(Mensuel!$C$4:$AN$4,2026,Mensuel!$C$44:$AN$44) -> 105.55556 | C18: =SUMIF(Mensuel!$C$4:$AN$4,2027,Mensuel!$C$44:$AN$44) -> 1577.7778 | D18: =SUMIF(Mensuel!$C$4:$AN$4,2028,Mensuel!$C$44:$AN$44) -> 2200 | E18: =SUMIF(Mensuel!$C$4:$AN$4,2029,Mensuel!$C$44:$AN$44) -> 2094.4444
A19: Charges financières | B19: =SUMIF(Mensuel!$C$4:$AN$4,2026,Mensuel!$C$48:$AN$48) -> 0 | C19: =SUMIF(Mensuel!$C$4:$AN$4,2027,Mensuel!$C$48:$AN$48) -> 2288.6099 | D19: =SUMIF(Mensuel!$C$4:$AN$4,2028,Mensuel!$C$48:$AN$48) -> 2015.9274 | E19: =SUMIF(Mensuel!$C$4:$AN$4,2029,Mensuel!$C$48:$AN$48) -> 1491.8897
A20: Subvention d'exploitation (Bourse French Tech) | B20: =SUMIF(Mensuel!$C$4:$AN$4,2026,Mensuel!$C$51:$AN$51) -> 0 | C20: =SUMIF(Mensuel!$C$4:$AN$4,2027,Mensuel!$C$51:$AN$51) -> 21000 | D20: =SUMIF(Mensuel!$C$4:$AN$4,2028,Mensuel!$C$51:$AN$51) -> 9000 | E20: =SUMIF(Mensuel!$C$4:$AN$4,2029,Mensuel!$C$51:$AN$51) -> 0
A21: Résultat avant impôt | B21: =SUMIF(Mensuel!$C$4:$AN$4,2026,Mensuel!$C$54:$AN$54) -> -13105.556 | C21: =SUMIF(Mensuel!$C$4:$AN$4,2027,Mensuel!$C$54:$AN$54) -> -96420.68 | D21: =SUMIF(Mensuel!$C$4:$AN$4,2028,Mensuel!$C$54:$AN$54) -> -80979.594 | E21: =SUMIF(Mensuel!$C$4:$AN$4,2029,Mensuel!$C$54:$AN$54) -> -16381.406
A22: Base imposable cumulée (report des déficits) | B22: 0 | C22: =B21+C21 -> -109526.24 | D22: =MIN(0,C22)+D21 -> -190505.83 | E22: =MIN(0,D22)+E21 -> -206887.24
A23: Impôt sur les sociétés | B23: 0 | C23: =IF(C22<=0,0,MIN(C22,42500)*Hypothèses!$B$82+MAX(0,C22-42500)*Hypothèses!$B$83) -> 0 | D23: =IF(D22<=0,0,MIN(D22,42500)*Hypothèses!$B$82+MAX(0,D22-42500)*Hypothèses!$B$83) -> 0 | E23: =IF(E22<=0,0,MIN(E22,42500)*Hypothèses!$B$82+MAX(0,E22-42500)*Hypothèses!$B$83) -> 0
A24: Résultat net | B24: =B21-B23 -> -13105.556 | C24: =C21-C23 -> -96420.68 | D24: =D21-D23 -> -80979.594 | E24: =E21-E23 -> -16381.406
A26: PLAN DE FINANCEMENT (€) | B26: Ante-création (nov.-déc. 26) | C26: 2027 | D26: 2028 | E26: 2029
A27: Capacité d'autofinancement (EBE − IS − intérêts) | B27: =B17-B23-B19+B20 -> -13000 | C27: =C17-C23-C19+C20 -> -94842.902 | D27: =D17-D23-D19+D20 -> -78779.594 | E27: =E17-E23-E19+E20 -> -14286.961
A28: Apport en capital des fondateurs | B28: =Hypothèses!$B$73 -> 10000 | C28: 0 | D28: 0 | E28: 0
A29: Comptes courants (prêts d'honneur des fondateurs) | B29: =Hypothèses!$B$74 -> 40000 | C29: 0 | D29: 0 | E29: 0
A30: Levée de fonds propres (business angels) | B30: 0 | C30: =Hypothèses!$B$80 -> 120000 | D30: 0 | E30: 0
A31: Emprunt bancaire | B31: 0 | C31: =Hypothèses!$B$77 -> 60000 | D31: 0 | E31: 0
A32: Total ressources (hors subvention, incluse dans la CAF) | B32: =SUM(B28:B31) -> 50000 | C32: =SUM(C28:C31) -> 180000 | D32: =SUM(D28:D31) -> 0 | E32: =SUM(E28:E31) -> 0
A33: Investissements matériels | B33: =SUMIF(Mensuel!$C$4:$AN$4,2026,Mensuel!$C$43:$AN$43) -> 3800 | C33: =SUMIF(Mensuel!$C$4:$AN$4,2027,Mensuel!$C$43:$AN$43) -> 2800 | D33: =SUMIF(Mensuel!$C$4:$AN$4,2028,Mensuel!$C$43:$AN$43) -> 0 | E33: =SUMIF(Mensuel!$C$4:$AN$4,2029,Mensuel!$C$43:$AN$43) -> 0
A34: Remboursement du capital emprunté | B34: =SUMIF(Mensuel!$C$4:$AN$4,2026,Mensuel!$C$49:$AN$49) -> 0 | C34: =SUMIF(Mensuel!$C$4:$AN$4,2027,Mensuel!$C$49:$AN$49) -> 10015.783 | D34: =SUMIF(Mensuel!$C$4:$AN$4,2028,Mensuel!$C$49:$AN$49) -> 11407.046 | E34: =SUMIF(Mensuel!$C$4:$AN$4,2029,Mensuel!$C$49:$AN$49) -> 11931.084
A35: Total emplois | B35: =B33+B34 -> 3800 | C35: =C33+C34 -> 12815.783 | D35: =D33+D34 -> 11407.046 | E35: =E33+E34 -> 11931.084
A36: Variation de trésorerie | B36: =B27+B32-B35 -> 33200 | C36: =C27+C32-C35 -> 72341.315 | D36: =D27+D32-D35 -> -90186.641 | E36: =E27+E32-E35 -> -26218.046
A37: Trésorerie de fin de période | B37: =Mensuel!D58 -> 33200 | C37: =Mensuel!P58 -> 105541.32 | D37: =Mensuel!AB58 -> 15354.674 | E37: =Mensuel!AN58 -> -10863.371
A38: Trésorerie mensuelle minimale de la période | B38: =MIN(Mensuel!C58:D58) -> 4500 | C38: =MIN(Mensuel!E58:P58) -> 65881.419 | D38: =MIN(Mensuel!Q58:AB58) -> 15354.674 | E38: =MIN(Mensuel!AC58:AN58) -> -15803.06
A40: KPI SaaS | B40: Ante-création (nov.-déc. 26) | C40: 2027 | D40: 2028 | E40: 2029
A41: Nouveaux domaines signés | C41: =SUMIF(Mensuel!$C$4:$AN$4,2027,Mensuel!$C$7:$AN$7) -> 25 | D41: =SUMIF(Mensuel!$C$4:$AN$4,2028,Mensuel!$C$7:$AN$7) -> 80 | E41: =SUMIF(Mensuel!$C$4:$AN$4,2029,Mensuel!$C$7:$AN$7) -> 130
A42: Domaines actifs au 31/12 | C42: =Mensuel!P9 -> 22.841355 | D42: =Mensuel!AB9 -> 85.724862 | E42: =Mensuel!AN9 -> 175.17527
A43: MRR de décembre | C43: =Mensuel!P14 -> 2718.1213 | D43: =Mensuel!AB14 -> 10201.259 | E43: =Mensuel!AN14 -> 20845.857
A44: ARR (MRR de décembre × 12) | C44: =C43*12 -> 32617.456 | D44: =D43*12 -> 122415.1 | E44: =E43*12 -> 250150.29
...
