Workbook

Sheet Lisez-moi
A1: MODÈLE FINANCIER — BUSINESS PLAN 3 ANS
A3: Structure : Hypothèses (toutes les entrées) → Trimestriel (moteur de calcul T1-T12) → Compte de résultat →
A4: Plan de financement → Seuil de rentabilité. Un chiffre modifié dans « Hypothèses » se propage partout.
A6: Code couleur : BLEU = hypothèse modifiable · NOIR = formule (ne pas écraser) · fond JAUNE = hypothèse clé.
A7: Unités : montants en € HT sauf mention « k€ » ; salaires en coûts chargés ; ETP = équivalents temps plein moyens.
A9: Statut des données : toutes les entrées sont des HYPOTHÈSES À VALIDER (colonne Justification), sauf mention
A10: [FAIT] avec source. Aucun chiffre d'illustration n'entre dans les calculs.
A12: Choix de modélisation (prudence assumée) :
A13: · Le CA est reconnu sur les salariés couverts MOYENS du trimestre (mi-période) — pas d'effet d'annonce ARR.
A14: · L'ARR affiché = salariés fin de période × prix moyen × 12 : c'est un run-rate, PAS le CA comptabilisé.
A15: · Pilotes : tous les pilotes paient 4 €/salarié/mois pendant 3 mois ; pour les convertis, ces sommes sont
A16: déduites du contrat — le modèle ne compte donc en CA pilote que les non-convertis (équivalent comptable).
... A22: Contrôles intégrés : lignes « Contrôle » (Trimestriel) et rapprochement trésorerie (Financement).

Sheet Hypothèses
A1: HYPOTHÈSES — cellules bleues modifiables
F2: Justification / statut
A3: 1 · Offre et prix
A4: Prix Essentiel (€/salarié/mois) | B4: 8 | F4: HYP n°1 à valider — test prix sur 20 DRH. Ancrage : Wellpass 1-20 €/sal/mois (seul benchmark public).
A5: Prix Patrimoine (€/salarié/mois) | B5: 15 | F5: HYP — haut de gamme QVT : se vend sur le ROI (coût d'un départ >> 15 €/mois).
A6: Prix pilote (€/salarié/mois — 3 mois, déduit si signature) | B6: 4 | F6: Décision d'offre. Corrige l'ancien « pilote gratuit » des documents Drive.
A7: Taux de conversion pilote → contrat | B7: 0.6 | F7: HYP — à mesurer dès les 5 premiers pilotes.
B9: An 1 | C9: An 2 | D9: An 3
A10: Part des salariés en offre Patrimoine | B10: 0.2 | C10: 0.28 | D10: 0.35 | F10: HYP « land & expand » : montée en gamme progressive. L'ancien BP supposait ~45 % dès l'an 1 sans le dire.
A11: Prix moyen pondéré (€/salarié/mois) | B11: =$B$4*(1-B10)+$B$5*B10 -> 9.4 | C11: =$B$4*(1-C10)+$B$5*C10 -> 9.96 | D11: =$B$4*(1-D10)+$B$5*D10 -> 10.45 | F11: Formule — 9,40 / 9,96 / 10,45 €.
A13: 2 · Commercial
A14: Nouveaux clients ETI (bruts) | B14: 15 | C14: 36 | D14: 75 | F14: Objectif volontariste — voir entonnoir (§3) et Tableaux_De_Bord pour le pilotage.
A15: Clients perdus (churn logo) | B15: 0 | C15: 1 | D15: 5 | F15: HYP — rétention logo > 90 %, conditionnée à l'activation (scénario central).
A16: Clients fin d'année (net) | B16: =B14-B15 -> 15 | C16: =B16+C14-C15 -> 50 | D16: =C16+D14-D15 -> 120
A17: Taille moyenne d'un client (salariés) | B17: 400 | C17: 500 | D17: 583.33 | F17: HYP — ETI 250-5 000 salariés ; la taille moyenne des comptes croît avec la maturité commerciale.
A18: Salariés couverts fin d'année | B18: =B16*B17 -> 6000 | C18: =C16*C17 -> 25000 | D18: =D16*D17 -> 69999.6 | F18: 6 000 / 25 000 / 70 000 — objectifs du socle conservés.
A20: 3 · Entonnoir commercial (taux de passage)
A21: Comptes travaillés → RDV obtenu | B21: 0.25 | F21: HYP — outbound LinkedIn + prescripteurs.
A22: RDV → démo qualifiée | B22: 0.5
A23: Démo → pilote | B23: 0.4 | F23: An 1 : 15 contrats ⇒ 25 pilotes ⇒ 63 démos ⇒ 125 RDV ⇒ 500 comptes travaillés (formules au Seuil).
A25: 4 · Adoption salariés (conditionne le renouvellement, pas le CA facturé)
A26: Activation à 3 mois — scénario CENTRAL | B26: 0.22 | F26: Benchmarks 04/08/2026 : RAND ~20 %, EAP digitaux 10-20 %, moyenne Moka.care ~20 % (04_BENCHMARKS.md).
A27: Activation — scénario BAS (seuil d'alerte) | B27: 0.12 | F27: Sous ce seuil : plan de relance (sponsoring interne, onboarding, relances managers).
A28: Activation — scénario HAUT (conditionné) | B28: 0.4 | F28: Niveau du meilleur client Moka.care. Exige sponsoring DG/managers + onboarding intégré. Ex-hypothèse unique du BP.
A30: 5 · Packs payés par le salarié
A31: Taux de souscription (% des salariés couverts, par an) | B31: 0.03 | C31: 0.05 | D31: 0.06 | F31: HYP — packs : consultation 79 € · fiscalité+déclaration 99 € · retraite 149 € · immobilier 179 €.
A32: Panier moyen (€) | B32: 110 | F32: HYP — mix des 4 packs.
A33: Reversement expert agréé (% du prix) | B33: 0.65 | F33: On facture un service, jamais une commission produit ; le CGP est payé à la consultation.
A35: 6 · Coûts variables (COGS)
A36: Infra, sécurité & coach IA (€/salarié/mois) | B36: 0.9 | C36: 0.8 | D36: 0.7 | F36: HYP — hébergement UE + inférence IA ; économies d'échelle.
A37: Support niveau 1 externalisé (€/salarié/mois) | B37: 0.4
A38: Coachs humains inclus (€/salarié Patrimoine/mois) | B38: 1.9 | F38: HYP — consommation ~15 %/an d'une session incluse à ~150 € de coût expert.
A39: Frais de facturation & paiement (% du CA) | B39: 0.015
A41: 7 · Équipe (ETP moyens sur l'année, coûts chargés)
A42: Rôle | B42: Coût chargé (k€/an) | C42: ETP An 1 | D42: ETP An 2 | E42: ETP An 3
A43: Fondatrice (CEO — vente, pilotage) | B43: 75 | C43: 1 | D43: 1 | E43: 1
A44: VP Sales | B44: 110 | C44: 0 | D44: 0.5 | E44: 1
A45: Account executives | B45: 80 | C45: 0.75 | D45: 2.5 | E45: 5
A46: SDR (prospection) | B46: 55 | C46: 0 | D46: 1 | E46: 2
A47: Customer success (1 CSM / ~20 clients) | B47: 58 | C47: 0.5 | D47: 3 | E47: 6
...

Sheet Trimestriel
A1: MOTEUR TRIMESTRIEL (T1-T12)
B2: T1 | C2: T2 | D2: T3 | E2: T4 | F2: T5 | G2: T6 | H2: T7 | I2: T8 | J2: T9 | K2: T10 | L2: T11 | M2: T12 | N2: An 1 | O2: An 2 | P2: An 3
A3: Clients et salariés couverts
A4: Nouveaux clients (bruts) | B4: 0 | C4: 2 | D4: 5 | E4: 8 | F4: 8 | G4: 9 | H4: 9 | I4: 10 | J4: 17 | K4: 18 | L4: 19 | M4: 21 | N4: =SUM(B4:E4) -> 15 | O4: =SUM(F4:I4) -> 36 | P4: =SUM(J4:M4) -> 75
A5: Clients perdus | B5: 0 | C5: 0 | D5: 0 | E5: 0 | F5: 0 | G5: 0 | H5: 0 | I5: 1 | J5: 1 | K5: 1 | L5: 1 | M5: 2 | N5: =SUM(B5:E5) -> 0 | O5: =SUM(F5:I5) -> 1 | P5: =SUM(J5:M5) -> 5
A6: Clients fin de trimestre | B6: =B4-B5 -> 0 | C6: =B6+C4-C5 -> 2 | D6: =C6+D4-D5 -> 7 | E6: =D6+E4-E5 -> 15 | F6: =E6+F4-F5 -> 23 | G6: =F6+G4-G5 -> 32 | H6: =G6+H4-H5 -> 41 | I6: =H6+I4-I5 -> 50 | J6: =I6+J4-J5 -> 66 | ... M6: =L6+M4-M5 -> 120 | N6: =E6 -> 15 | O6: =I6 -> 50 | P6: =M6 -> 120
A7: Taille moyenne (salariés/client) | B7: =Hypothèses!B$17 -> 400 | C7: =Hypothèses!B$17 -> 400 | D7: =Hypothèses!B$17 -> 400 | E7: =Hypothèses!B$17 -> 400 | F7: =Hypothèses!C$17 -> 500 | G7: =Hypothèses!C$17 -> 500 | H7: =Hypothèses!C$17 -> 500 | I7: =Hypothèses!C$17 -> 500 | J7: =Hypothèses!D$17 -> 583.33 | K7: =Hypothèses!D$17 -> 583.33 | L7: =Hypothèses!D$17 -> 583.33 | M7: =Hypothèses!D$17 -> 583.33 | N7: =E7 -> 400 | O7: =I7 -> 500 | P7: =M7 -> 583.33
A8: Salariés couverts (fin) | B8: =B6*B7 -> 0 | C8: =C6*C7 -> 800 | D8: =D6*D7 -> 2800 | E8: =E6*E7 -> 6000 | F8: =F6*F7 -> 11500 | G8: =G6*G7 -> 16000 | H8: =H6*H7 -> 20500 | I8: =I6*I7 -> 25000 | ... M8: =M6*M7 -> 69999.6 | N8: =E8 -> 6000 | O8: =I8 -> 25000 | P8: =M8 -> 69999.6
A9: Salariés couverts (moyens) | B9: =B8/2 -> 0 | C9: =(B8+C8)/2 -> 400 | D9: =(C8+D8)/2 -> 1800 | E9: =(D8+E8)/2 -> 4400 | F9: =(E8+F8)/2 -> 8750 | G9: =(F8+G8)/2 -> 13750 | H9: =(G8+H8)/2 -> 18250 | I9: =(H8+I8)/2 -> 22750 | J9: =(I8+J8)/2 -> 31749.89 | ... M9: =(L8+M8)/2 -> 64457.965 | N9: =E9 -> 4400 | O9: =I9 -> 22750 | P9: =M9 -> 64457.965
A10: Contrôle : nouveaux clients = Hypothèses (0 attendu) | N10: =SUM(B4:E4)-Hypothèses!B14 -> 0 | O10: =SUM(F4:I4)-Hypothèses!C14 -> 0 | P10: =SUM(J4:M4)-Hypothèses!D14 -> 0
A11: Revenus
A12: Prix moyen (€/salarié/mois) | B12: =Hypothèses!B$11 -> 9.4 | C12: =Hypothèses!B$11 -> 9.4 | D12: =Hypothèses!B$11 -> 9.4 | E12: =Hypothèses!B$11 -> 9.4 | F12: =Hypothèses!C$11 -> 9.96 | G12: =Hypothèses!C$11 -> 9.96 | H12: =Hypothèses!C$11 -> 9.96 | I12: =Hypothèses!C$11 -> 9.96 | J12: =Hypothèses!D$11 -> 10.45 | K12: =Hypothèses!D$11 -> 10.45 | L12: =Hypothèses!D$11 -> 10.45 | M12: =Hypothèses!D$11 -> 10.45 | N12: =E12 -> 9.4 | O12: =I12 -> 9.96 | P12: =M12 -> 10.45
A13: CA abonnements | B13: =B9*B12*3 -> 0 | C13: =C9*C12*3 -> 11280 | D13: =D9*D12*3 -> 50760 | E13: =E9*E12*3 -> 124080 | F13: =F9*F12*3 -> 261450 | G13: =G9*G12*3 -> 410850 | H13: =H9*H12*3 -> 545310 | I13: =I9*I12*3 -> 679770 | ... M13: =M9*M12*3 -> 2020757.2 | N13: =SUM(B13:E13) -> 186120 | O13: =SUM(F13:I13) -> 1897380 | P13: =SUM(J13:M13) -> 6060967.6
A14: Pilotes menés (nb) | B14: =B4/Hypothèses!$B$7 -> 0 | C14: =C4/Hypothèses!$B$7 -> 3.3333333 | D14: =D4/Hypothèses!$B$7 -> 8.3333333 | E14: =E4/Hypothèses!$B$7 -> 13.333333 | F14: =F4/Hypothèses!$B$7 -> 13.333333 | G14: =G4/Hypothèses!$B$7 -> 15 | H14: =H4/Hypothèses!$B$7 -> 15 | I14: =I4/Hypothèses!$B$7 -> 16.666667 | ... M14: =M4/Hypothèses!$B$7 -> 35 | N14: =SUM(B14:E14) -> 25 | O14: =SUM(F14:I14) -> 60 | P14: =SUM(J14:M14) -> 125
A15: CA pilotes (non convertis) | B15: =B14*(1-Hypothèses!$B$7)*B7*Hypothèses!$B$6*3 -> 0 | C15: =C14*(1-Hypothèses!$B$7)*C7*Hypothèses!$B$6*3 -> 6400 | D15: =D14*(1-Hypothèses!$B$7)*D7*Hypothèses!$B$6*3 -> 16000 | E15: =E14*(1-Hypothèses!$B$7)*E7*Hypothèses!$B$6*3 -> 25600 | F15: =F14*(1-Hypothèses!$B$7)*F7*Hypothèses!$B$6*3 -> 32000 | G15: =G14*(1-Hypothèses!$B$7)*G7*Hypothèses!$B$6*3 -> 36000 | H15: =H14*(1-Hypothèses!$B$7)*H7*Hypothèses!$B$6*3 -> 36000 | I15: =I14*(1-Hypothèses!$B$7)*I7*Hypothèses!$B$6*3 -> 40000 | ... M15: =M14*(1-Hypothèses!$B$7)*M7*Hypothèses!$B$6*3 -> 97999.44 | N15: =SUM(B15:E15) -> 48000 | O15: =SUM(F15:I15) -> 144000 | P15: =SUM(J15:M15) -> 349998
A16: CA packs salariés | B16: =B9*Hypothèses!B$31/4*Hypothèses!$B$32 -> 0 | C16: =C9*Hypothèses!B$31/4*Hypothèses!$B$32 -> 330 | D16: =D9*Hypothèses!B$31/4*Hypothèses!$B$32 -> 1485 | E16: =E9*Hypothèses!B$31/4*Hypothèses!$B$32 -> 3630 | F16: =F9*Hypothèses!C$31/4*Hypothèses!$B$32 -> 12031.25 | G16: =G9*Hypothèses!C$31/4*Hypothèses!$B$32 -> 18906.25 | H16: =H9*Hypothèses!C$31/4*Hypothèses!$B$32 -> 25093.75 | I16: =I9*Hypothèses!C$31/4*Hypothèses!$B$32 -> 31281.25 | J16: =J9*Hypothèses!D$31/4*Hypothèses!$B$32 -> 52387.319 | K16: =K9*Hypothèses!D$31/4*Hypothèses!$B$32 -> 71705.84 | L16: =L9*Hypothèses!D$31/4*Hypothèses!$B$32 -> 88549.494 | M16: =M9*Hypothèses!D$31/4*Hypothèses!$B$32 -> 106355.64 | N16: =SUM(B16:E16) -> 5445 | O16: =SUM(F16:I16) -> 87312.5 | P16: =SUM(J16:M16) -> 318998.29
A17: Chiffre d'affaires total | B17: =B13+B15+B16 -> 0 | C17: =C13+C15+C16 -> 18010 | D17: =D13+D15+D16 -> 68245 | E17: =E13+E15+E16 -> 153310 | F17: =F13+F15+F16 -> 305481.25 | G17: =G13+G15+G16 -> 465756.25 | H17: =H13+H15+H16 -> 606403.75 | I17: =I13+I15+I16 -> 751051.25 | ... M17: =M13+M15+M16 -> 2225112.3 | N17: =SUM(B17:E17) -> 239565 | O17: =SUM(F17:I17) -> 2128692.5 | P17: =SUM(J17:M17) -> 6729963.9
A18: Coûts variables (COGS)
A19: Infra, sécurité & IA | B19: =B9*Hypothèses!B$36*3 -> 0 | C19: =C9*Hypothèses!B$36*3 -> 1080 | D19: =D9*Hypothèses!B$36*3 -> 4860 | E19: =E9*Hypothèses!B$36*3 -> 11880 | F19: =F9*Hypothèses!C$36*3 -> 21000 | G19: =G9*Hypothèses!C$36*3 -> 33000 | H19: =H9*Hypothèses!C$36*3 -> 43800 | I19: =I9*Hypothèses!C$36*3 -> 54600 | J19: =J9*Hypothèses!D$36*3 -> 66674.769 | K19: =K9*Hypothèses!D$36*3 -> 91261.978 | L19: =L9*Hypothèses!D$36*3 -> 112699.36 | M19: =M9*Hypothèses!D$36*3 -> 135361.73 | N19: =SUM(B19:E19) -> 17820 | O19: =SUM(F19:I19) -> 152400 | P19: =SUM(J19:M19) -> 405997.83
A20: Support niveau 1 | B20: =B9*Hypothèses!$B$37*3 -> 0 | C20: =C9*Hypothèses!$B$37*3 -> 480 | D20: =D9*Hypothèses!$B$37*3 -> 2160 | E20: =E9*Hypothèses!$B$37*3 -> 5280 | F20: =F9*Hypothèses!$B$37*3 -> 10500 | G20: =G9*Hypothèses!$B$37*3 -> 16500 | H20: =H9*Hypothèses!$B$37*3 -> 21900 | I20: =I9*Hypothèses!$B$37*3 -> 27300 | ... M20: =M9*Hypothèses!$B$37*3 -> 77349.558 | N20: =SUM(B20:E20) -> 7920 | O20: =SUM(F20:I20) -> 76200 | P20: =SUM(J20:M20) -> 231998.76
A21: Coachs humains inclus (Patrimoine) | B21: =B9*Hypothèses!B$10*Hypothèses!$B$38*3 -> 0 | C21: =C9*Hypothèses!B$10*Hypothèses!$B$38*3 -> 456 | D21: =D9*Hypothèses!B$10*Hypothèses!$B$38*3 -> 2052 | E21: =E9*Hypothèses!B$10*Hypothèses!$B$38*3 -> 5016 | F21: =F9*Hypothèses!C$10*Hypothèses!$B$38*3 -> 13965 | G21: =G9*Hypothèses!C$10*Hypothèses!$B$38*3 -> 21945 | H21: =H9*Hypothèses!C$10*Hypothèses!$B$38*3 -> 29127 | I21: =I9*Hypothèses!C$10*Hypothèses!$B$38*3 -> 36309 | J21: =J9*Hypothèses!D$10*Hypothèses!$B$38*3 -> 63341.031 | K21: =K9*Hypothèses!D$10*Hypothèses!$B$38*3 -> 86698.88 | L21: =L9*Hypothèses!D$10*Hypothèses!$B$38*3 -> 107064.39 | M21: =M9*Hypothèses!D$10*Hypothèses!$B$38*3 -> 128593.64 | N21: =SUM(B21:E21) -> 7524 | O21: =SUM(F21:I21) -> 101346 | P21: =SUM(J21:M21) -> 385697.94
A22: Facturation & paiement | B22: =B17*Hypothèses!$B$39 -> 0 | C22: =C17*Hypothèses!$B$39 -> 270.15 | D22: =D17*Hypothèses!$B$39 -> 1023.675 | E22: =E17*Hypothèses!$B$39 -> 2299.65 | F22: =F17*Hypothèses!$B$39 -> 4582.2188 | G22: =G17*Hypothèses!$B$39 -> 6986.3438 | H22: =H17*Hypothèses!$B$39 -> 9096.0562 | I22: =I17*Hypothèses!$B$39 -> 11265.769 | ... M22: =M17*Hypothèses!$B$39 -> 33376.684 | N22: =SUM(B22:E22) -> 3593.475 | O22: =SUM(F22:I22) -> 31930.388 | P22: =SUM(J22:M22) -> 100949.46
A23: Reversement experts (packs) | B23: =B16*Hypothèses!$B$33 -> 0 | C23: =C16*Hypothèses!$B$33 -> 214.5 | D23: =D16*Hypothèses!$B$33 -> 965.25 | E23: =E16*Hypothèses!$B$33 -> 2359.5 | F23: =F16*Hypothèses!$B$33 -> 7820.3125 | G23: =G16*Hypothèses!$B$33 -> 12289.062 | H23: =H16*Hypothèses!$B$33 -> 16310.938 | I23: =I16*Hypothèses!$B$33 -> 20332.812 | ... M23: =M16*Hypothèses!$B$33 -> 69131.167 | N23: =SUM(B23:E23) -> 3539.25 | O23: =SUM(F23:I23) -> 56753.125 | P23: =SUM(J23:M23) -> 207348.89
A24: COGS total | B24: =SUM(B19:B23) -> 0 | C24: =SUM(C19:C23) -> 2500.65 | D24: =SUM(D19:D23) -> 11060.925 | E24: =SUM(E19:E23) -> 26835.15 | F24: =SUM(F19:F23) -> 57867.531 | G24: =SUM(G19:G23) -> 90720.406 | H24: =SUM(H19:H23) -> 120233.99 | I24: =SUM(I19:I23) -> 149807.58 | ... M24: =SUM(M19:M23) -> 443812.78 | N24: =SUM(B24:E24) -> 40396.725 | O24: =SUM(F24:I24) -> 418629.51 | P24: =SUM(J24:M24) -> 1331992.9
A25: Marge brute | B25: =B17-B24 -> 0 | C25: =C17-C24 -> 15509.35 | D25: =D17-D24 -> 57184.075 | E25: =E17-E24 -> 126474.85 | F25: =F17-F24 -> 247613.72 | G25: =G17-G24 -> 375035.84 | H25: =H17-H24 -> 486169.76 | I25: =I17-I24 -> 601243.67 | ... M25: =M17-M24 -> 1781299.5 | N25: =SUM(B25:E25) -> 199168.27 | O25: =SUM(F25:I25) -> 1710063 | P25: =SUM(J25:M25) -> 5397971
A26: Marge brute (%) | B26: =IFERROR(B25/B17,"") | C26: =IFERROR(C25/C17,"") -> 0.86115214 | D26: =IFERROR(D25/D17,"") -> 0.83792329 | E26: =IFERROR(E25/E17,"") -> 0.82496152 | F26: =IFERROR(F25/F17,"") -> 0.81056929 | G26: =IFERROR(G25/G17,"") -> 0.80521913 | H26: =IFERROR(H25/H17,"") -> 0.80172617 | I26: =IFERROR(I25/I17,"") -> 0.80053614 | ... P26: =IFERROR(P25/P17,"") -> 0.80208023
A27: Charges fixes
A28: Masse salariale | B28: =Hypothèses!C$54/4*1000 -> 64685 | C28: =Hypothèses!C$54/4*1000 -> 64685 | D28: =Hypothèses!C$54/4*1000 -> 64685 | E28: =Hypothèses!C$54/4*1000 -> 64685 | F28: =Hypothèses!D$54/4*1000 -> 241500 | G28: =Hypothèses!D$54/4*1000 -> 241500 | H28: =Hypothèses!D$54/4*1000 -> 241500 | I28: =Hypothèses!D$54/4*1000 -> 241500 | J28: =Hypothèses!E$54/4*1000 -> 490375 | K28: =Hypothèses!E$54/4*1000 -> 490375 | L28: =Hypothèses!E$54/4*1000 -> 490375 | M28: =Hypothèses!E$54/4*1000 -> 490375 | N28: =SUM(B28:E28) -> 258740 | O28: =SUM(F28:I28) -> 966000 | P28: =SUM(J28:M28) -> 1961500
A29: Studio de développement | B29: =Hypothèses!B$57/4*1000 -> 75000 | C29: =Hypothèses!B$57/4*1000 -> 75000 | D29: =Hypothèses!B$57/4*1000 -> 75000 | E29: =Hypothèses!B$57/4*1000 -> 75000 | F29: =Hypothèses!C$57/4*1000 -> 87500 | G29: =Hypothèses!C$57/4*1000 -> 87500 | H29: =Hypothèses!C$57/4*1000 -> 87500 | I29: =Hypothèses!C$57/4*1000 -> 87500 | J29: =Hypothèses!D$57/4*1000 -> 37500 | K29: =Hypothèses!D$57/4*1000 -> 37500 | L29: =Hypothèses!D$57/4*1000 -> 37500 | M29: =Hypothèses!D$57/4*1000 -> 37500 | N29: =SUM(B29:E29) -> 300000 | O29: =SUM(F29:I29) -> 350000 | P29: =SUM(J29:M29) -> 150000
A30: Marketing & marque | B30: =Hypothèses!B$58/4*1000 -> 15000 | C30: =Hypothèses!B$58/4*1000 -> 15000 | D30: =Hypothèses!B$58/4*1000 -> 15000 | E30: =Hypothèses!B$58/4*1000 -> 15000 | F30: =Hypothèses!C$58/4*1000 -> 75000 | G30: =Hypothèses!C$58/4*1000 -> 75000 | H30: =Hypothèses!C$58/4*1000 -> 75000 | I30: =Hypothèses!C$58/4*1000 -> 75000 | J30: =Hypothèses!D$58/4*1000 -> 175000 | K30: =Hypothèses!D$58/4*1000 -> 175000 | L30: =Hypothèses!D$58/4*1000 -> 175000 | M30: =Hypothèses!D$58/4*1000 -> 175000 | N30: =SUM(B30:E30) -> 60000 | O30: =SUM(F30:I30) -> 300000 | P30: =SUM(J30:M30) -> 700000
A31: Commissions prescripteurs | B31: =B13*Hypothèses!B$59 -> 0 | C31: =C13*Hypothèses!B$59 -> 0 | D31: =D13*Hypothèses!B$59 -> 0 | E31: =E13*Hypothèses!B$59 -> 0 | F31: =F13*Hypothèses!C$59 -> 5229 | G31: =G13*Hypothèses!C$59 -> 8217 | H31: =H13*Hypothèses!C$59 -> 10906.2 | I31: =I13*Hypothèses!C$59 -> 13595.4 | J31: =J13*Hypothèses!D$59 -> 37325.964 | K31: =K13*Hypothèses!D$59 -> 51090.411 | L31: =L13*Hypothèses!D$59 -> 63091.514 | M31: =M13*Hypothèses!D$59 -> 75778.395 | N31: =SUM(B31:E31) -> 0 | O31: =SUM(F31:I31) -> 37947.6 | P31: =SUM(J31:M31) -> 227286.29
A32: Juridique & conformité | B32: =Hypothèses!B$60/4*1000 -> 11250 | C32: =Hypothèses!B$60/4*1000 -> 11250 | D32: =Hypothèses!B$60/4*1000 -> 11250 | E32: =Hypothèses!B$60/4*1000 -> 11250 | F32: =Hypothèses!C$60/4*1000 -> 13750 | G32: =Hypothèses!C$60/4*1000 -> 13750 | H32: =Hypothèses!C$60/4*1000 -> 13750 | I32: =Hypothèses!C$60/4*1000 -> 13750 | J32: =Hypothèses!D$60/4*1000 -> 20000 | K32: =Hypothèses!D$60/4*1000 -> 20000 | L32: =Hypothèses!D$60/4*1000 -> 20000 | M32: =Hypothèses!D$60/4*1000 -> 20000 | N32: =SUM(B32:E32) -> 45000 | O32: =SUM(F32:I32) -> 55000 | P32: =SUM(J32:M32) -> 80000
A33: G&A (loyers, outils, assurances) | B33: =Hypothèses!B$61/4*1000 -> 12500 | C33: =Hypothèses!B$61/4*1000 -> 12500 | D33: =Hypothèses!B$61/4*1000 -> 12500 | E33: =Hypothèses!B$61/4*1000 -> 12500 | F33: =Hypothèses!C$61/4*1000 -> 27500 | G33: =Hypothèses!C$61/4*1000 -> 27500 | H33: =Hypothèses!C$61/4*1000 -> 27500 | I33: =Hypothèses!C$61/4*1000 -> 27500 | J33: =Hypothèses!D$61/4*1000 -> 55000 | K33: =Hypothèses!D$61/4*1000 -> 55000 | L33: =Hypothèses!D$61/4*1000 -> 55000 | M33: =Hypothèses!D$61/4*1000 -> 55000 | N33: =SUM(B33:E33) -> 50000 | O33: =SUM(F33:I33) -> 110000 | P33: =SUM(J33:M33) -> 220000
A34: Recrutement + audit sécurité | B34: =(Hypothèses!B$62+Hypothèses!B$63)/4*1000 -> 3750 | C34: =(Hypothèses!B$62+Hypothèses!B$63)/4*1000 -> 3750 | D34: =(Hypothèses!B$62+Hypothèses!B$63)/4*1000 -> 3750 | E34: =(Hypothèses!B$62+Hypothèses!B$63)/4*1000 -> 3750 | F34: =(Hypothèses!C$62+Hypothèses!C$63)/4*1000 -> 16250 | G34: =(Hypothèses!C$62+Hypothèses!C$63)/4*1000 -> 16250 | H34: =(Hypothèses!C$62+Hypothèses!C$63)/4*1000 -> 16250 | I34: =(Hypothèses!C$62+Hypothèses!C$63)/4*1000 -> 16250 | J34: =(Hypothèses!D$62+Hypothèses!D$63)/4*1000 -> 26250 | K34: =(Hypothèses!D$62+Hypothèses!D$63)/4*1000 -> 26250 | L34: =(Hypothèses!D$62+Hypothèses!D$63)/4*1000 -> 26250 | M34: =(Hypothèses!D$62+Hypothèses!D$63)/4*1000 -> 26250 | N34: =SUM(B34:E34) -> 15000 | O34: =SUM(F34:I34) -> 65000 | P34: =SUM(J34:M34) -> 105000
A35: Charges fixes totales | B35: =SUM(B28:B34) -> 182185 | C35: =SUM(C28:C34) -> 182185 | D35: =SUM(D28:D34) -> 182185 | E35: =SUM(E28:E34) -> 182185 | F35: =SUM(F28:F34) -> 466729 | G35: =SUM(G28:G34) -> 469717 | H35: =SUM(H28:H34) -> 472406.2 | I35: =SUM(I28:I34) -> 475095.4 | ... M35: =SUM(M28:M34) -> 879903.4 | N35: =SUM(B35:E35) -> 728740 | O35: =SUM(F35:I35) -> 1883947.6 | P35: =SUM(J35:M35) -> 3443786.3
A36: EBITDA | B36: =B25-B35 -> -182185 | C36: =C25-C35 -> -166675.65 | D36: =D25-D35 -> -125000.93 | E36: =E25-E35 -> -55710.15 | F36: =F25-F35 -> -219115.28 | G36: =G25-G35 -> -94681.156 | H36: =H25-H35 -> 13763.556 | I36: =I25-I35 -> 126148.27 | ... M36: =M25-M35 -> 901396.11 | N36: =SUM(B36:E36) -> -529571.72 | O36: =SUM(F36:I36) -> -173884.61 | P36: =SUM(J36:M36) -> 1954184.7
A37: Trésorerie
A38: Capex | B38: =Hypothèses!B$71 -> 5000 | C38: =Hypothèses!B$71 -> 5000 | D38: =Hypothèses!B$71 -> 5000 | E38: =Hypothèses!B$71 -> 5000 | F38: =Hypothèses!C$71 -> 6000 | G38: =Hypothèses!C$71 -> 6000 | H38: =Hypothèses!C$71 -> 6000 | I38: =Hypothèses!C$71 -> 6000 | J38: =Hypothèses!D$71 -> 8000 | K38: =Hypothèses!D$71 -> 8000 | L38: =Hypothèses!D$71 -> 8000 | M38: =Hypothèses!D$71 -> 8000 | N38: =SUM(B38:E38) -> 20000 | O38: =SUM(F38:I38) -> 24000 | P38: =SUM(J38:M38) -> 32000
A39: Variation de BFR | B39: =Hypothèses!B$75*1000/4 -> 5000 | C39: =Hypothèses!B$75*1000/4 -> 5000 | D39: =Hypothèses!B$75*1000/4 -> 5000 | E39: =Hypothèses!B$75*1000/4 -> 5000 | F39: =Hypothèses!C$75*1000/4 -> 10000 | G39: =Hypothèses!C$75*1000/4 -> 10000 | H39: =Hypothèses!C$75*1000/4 -> 10000 | I39: =Hypothèses!C$75*1000/4 -> 10000 | J39: =Hypothèses!D$75*1000/4 -> 15000 | K39: =Hypothèses!D$75*1000/4 -> 15000 | L39: =Hypothèses!D$75*1000/4 -> 15000 | M39: =Hypothèses!D$75*1000/4 -> 15000 | N39: =SUM(B39:E39) -> 20000 | O39: =SUM(F39:I39) -> 40000 | P39: =SUM(J39:M39) -> 60000
A40: IS décaissé + remboursement prêt | B40: 0 | C40: 0 | D40: 0 | E40: 0 | F40: 0 | G40: 0 | H40: 0 | I40: 0 | J40: 0 | K40: 0 | L40: 0 | M40: =-'Compte de résultat'!D20+Hypothèses!$B$74 -> 317682.1 | N40: =SUM(B40:E40) -> 0 | O40: =SUM(F40:I40) -> 0 | P40: =SUM(J40:M40) -> 317682.1
...

Sheet Compte de résultat
A1: COMPTE DE RÉSULTAT PRÉVISIONNEL — 3 ANS (€, HT)
A2: 15 lignes — format imposé par la grille de soutenance (slide « compte de résultat »).
B3: An 1 | C3: An 2 | D3: An 3
A4: CA abonnements (employeurs) | B4: =Trimestriel!N13 -> 186120 | C4: =Trimestriel!O13 -> 1897380 | D4: =Trimestriel!P13 -> 6060967.6
A5: CA pilotes | B5: =Trimestriel!N15 -> 48000 | C5: =Trimestriel!O15 -> 144000 | D5: =Trimestriel!P15 -> 349998
A6: CA packs (salariés) | B6: =Trimestriel!N16 -> 5445 | C6: =Trimestriel!O16 -> 87312.5 | D6: =Trimestriel!P16 -> 318998.29
A7: Chiffre d'affaires total | B7: =SUM(B4:B6) -> 239565 | C7: =SUM(C4:C6) -> 2128692.5 | D7: =SUM(D4:D6) -> 6729963.9
A8: Coûts variables (COGS) | B8: =-Trimestriel!N24 -> -40396.725 | C8: =-Trimestriel!O24 -> -418629.51 | D8: =-Trimestriel!P24 -> -1331992.9
A9: Marge brute | B9: =B7+B8 -> 199168.27 | C9: =C7+C8 -> 1710063 | D9: =D7+D8 -> 5397971 | F9: ≈ 80 % — cohérent avec l'hypothèse « ~78-80 % » du socle.
A10: Masse salariale | B10: =-Trimestriel!N28 -> -258740 | C10: =-Trimestriel!O28 -> -966000 | D10: =-Trimestriel!P28 -> -1961500
A11: Développement externalisé (studio) | B11: =-Trimestriel!N29 -> -300000 | C11: =-Trimestriel!O29 -> -350000 | D11: =-Trimestriel!P29 -> -150000
A12: Marketing & commissions prescripteurs | B12: =-Trimestriel!N30-Trimestriel!N31 -> -60000 | C12: =-Trimestriel!O30-Trimestriel!O31 -> -337947.6 | D12: =-Trimestriel!P30-Trimestriel!P31 -> -927286.29
A13: Frais généraux, juridique, conformité | B13: =-Trimestriel!N32-Trimestriel!N33-Trimestriel!N34 -> -110000 | C13: =-Trimestriel!O32-Trimestriel!O33-Trimestriel!O34 -> -230000 | D13: =-Trimestriel!P32-Trimestriel!P33-Trimestriel!P34 -> -405000
A14: EBITDA | B14: =B9+SUM(B10:B13) -> -529571.72 | C14: =C9+SUM(C10:C13) -> -173884.61 | D14: =D9+SUM(D10:D13) -> 1954184.7
A15: EBITDA (% du CA) | B15: =IFERROR(B14/B7,"") -> -2.2105555 | C15: =IFERROR(C14/C7,"") -> -0.081686111 | D15: =IFERROR(D14/D7,"") -> 0.29037076
A16: Amortissements | B16: =-Hypothèses!B72*1000 -> -10000 | C16: =-Hypothèses!C72*1000 -> -20000 | D16: =-Hypothèses!D72*1000 -> -30000
A17: Résultat d'exploitation | B17: =B14+B16 -> -539571.72 | C17: =C14+C16 -> -193884.61 | D17: =D14+D16 -> 1924184.7
A18: Déficits reportables imputés (an 3) | B18: 0 | C18: 0 | D18: =MIN(0,B17)+MIN(0,C17) -> -733456.34
A19: Résultat imposable (après reports) | B19: =MIN(0,B17) -> -539571.72 | C19: =MIN(0,C17) -> -193884.61 | D19: =MAX(0,D17+D18) -> 1190728.4
A20: Impôt sur les sociétés | B20: =-MAX(0,B19)*Hypothèses!$B$73 -> 0 | C20: =-MAX(0,C19)*Hypothèses!$B$73 -> 0 | D20: =-MAX(0,D19)*Hypothèses!$B$73 -> -297682.1
A21: Résultat net | B21: =B17+B20 -> -539571.72 | C21: =C17+C20 -> -193884.61 | D21: =D17+D20 -> 1626502.6
A23: Indicateurs clés (découlent du modèle)
A24: ARR fin d'année (run-rate) | B24: =Trimestriel!N45 -> 676800 | C24: =Trimestriel!O45 -> 2988000 | D24: =Trimestriel!P45 -> 8777949.8 | F24: 0,68 / 3,0 / 8,8 M€ — remplace l'ancien « 0,8 / 3,5 / 9,5 » qui confondait ARR et CA.
A25: Clients fin d'année | B25: =Trimestriel!N6 -> 15 | C25: =Trimestriel!O6 -> 50 | D25: =Trimestriel!P6 -> 120
A26: Salariés couverts fin d'année | B26: =Trimestriel!N8 -> 6000 | C26: =Trimestriel!O8 -> 25000 | D26: =Trimestriel!P8 -> 69999.6
A27: Marge brute % | B27: =Trimestriel!N26 -> 0.83137468 | C27: =Trimestriel!O26 -> 0.8033396 | D27: =Trimestriel!P26 -> 0.80208023
A28: CAC (S&M / nouveaux clients, €) | B28: =(SUMPRODUCT(Hypothèses!$B$44:$B$46,Hypothèses!C44:C46)*1000+Trimestriel!N30+Trimestriel!N31)/Hypothèses!B14 -> 8000 | C28: =(SUMPRODUCT(Hypothèses!$B$44:$B$46,Hypothèses!D44:D46)*1000+Trimestriel!O30+Trimestriel!O31)/Hypothèses!C14 -> 17998.544 | D28: =(SUMPRODUCT(Hypothèses!$B$44:$B$46,Hypothèses!E44:E46)*1000+Trimestriel!P30+Trimestriel!P31)/Hypothèses!D14 -> 20630.484 | F28: S&M = VP Sales + AE + SDR + marketing + commissions. An 2 ≈ 18 k€/client.
A29: ARR apporté par nouveau client (€) | B29: =Hypothèses!B17*Hypothèses!B11*12 -> 45120 | C29: =Hypothèses!C17*Hypothèses!C11*12 -> 59760 | D29: =Hypothèses!D17*Hypothèses!D11*12 -> 73149.582
A30: Payback CAC (mois, sur marge brute) | B30: =IFERROR(B28/(B29*Trimestriel!N26/12),"") -> 2.5592066 | C30: =IFERROR(C28/(C29*Trimestriel!O26/12),"") -> 4.4989262 | D30: =IFERROR(D28/(D29*Trimestriel!P26/12),"") -> 4.2195 | F30: ≈ 4-5 mois an 2 — excellent pour du SaaS B2B (référence : < 12 mois).

Sheet Financement
A1: PLAN DE FINANCEMENT — ANTE-CRÉATION + 3 ANS (€)
B3: Ante-création | C3: An 1 | D3: An 2 | E3: An 3
A4: Emplois (besoins)
A5: Frais d'établissement, marque, étude, maquette | B5: =Hypothèses!B70 -> 60000
A6: Capex matériel | C6: =Trimestriel!N38 -> 20000 | D6: =Trimestriel!O38 -> 24000 | E6: =Trimestriel!P38 -> 32000
A7: Variation de BFR | C7: =Trimestriel!N39 -> 20000 | D7: =Trimestriel!O39 -> 40000 | E7: =Trimestriel!P39 -> 60000
A8: Insuffisance d'autofinancement (pertes − amortissements) | C8: =MAX(0,-('Compte de résultat'!B21+Hypothèses!B72*1000)) -> 529571.72 | D8: =MAX(0,-('Compte de résultat'!C21+Hypothèses!C72*1000)) -> 173884.61 | E8: 0
A9: Remboursement prêt d'honneur | E9: =Hypothèses!B74 -> 20000
A10: Total emplois | B10: =SUM(B5:B9) -> 60000 | C10: =SUM(C5:C9) -> 569571.72 | D10: =SUM(D5:D9) -> 237884.61 | E10: =SUM(E5:E9) -> 112000
A11: Ressources
A12: Apport fondatrice | B12: =Hypothèses!B67 -> 30000
A13: Prêt d'honneur | B13: =Hypothèses!B68 -> 20000
A14: Subvention (à confirmer) | B14: =Hypothèses!B69 -> 30000
A15: Levée de fonds (seed) | C15: =Hypothèses!B66 -> 1500000 | G15: Encaissée au T1 an 1 — le tour se signe À LA CRÉATION, pas « à 18 mois » (incohérence corrigée).
A16: Capacité d'autofinancement (RN + amortissements) | C16: 0 | D16: 0 | E16: =MAX(0,'Compte de résultat'!D21+Hypothèses!D72*1000) -> 1656502.6
A17: Total ressources | B17: =SUM(B12:B16) -> 80000 | C17: =SUM(C12:C16) -> 1500000 | D17: =SUM(D12:D16) -> 0 | E17: =SUM(E12:E16) -> 1656502.6
A19: Solde annuel | B19: =B17-B10 -> 20000 | C19: =C17-C10 -> 930428.28 | D19: =D17-D10 -> -237884.61 | E19: =E17-E10 -> 1544502.6
A20: Trésorerie cumulée | B20: =B19 -> 20000 | C20: =B20+C19 -> 950428.28 | D20: =C20+D19 -> 712543.66 | E20: =D20+E19 -> 2257046.3
A22: Contrôle : trésorerie cumulée an 3 − trésorerie Trimestriel T12 (écart d'arrondi attendu ≈ 0) | B22: =E20-Trimestriel!M43 -> 0

Sheet Seuil de rentabilité
A1: SEUIL DE RENTABILITÉ, POINT MORT, BESOIN DE FINANCEMENT
A3: Point mort — traduit en quantités (exigence de la grille)
B4: Structure an 2 | C4: Structure an 3
A5: Charges fixes trimestrielles (€) | B5: =Trimestriel!O35/4 -> 470986.9 | C5: =Trimestriel!P35/4 -> 860946.57
A6: Marge brute par salarié couvert et par trimestre (€) | B6: =Hypothèses!C11*3*Trimestriel!O26 -> 24.003787 | C6: =Hypothèses!D11*3*Trimestriel!P26 -> 25.145215
A7: SEUIL : salariés couverts nécessaires | B7: =B5/B6 -> 19621.358 | C7: =C5/C6 -> 34238.982 | F7: ≈ 20 000 salariés (structure an 2) / ≈ 36 000 (structure an 3, coûts pleins).
A8: SEUIL : en nombre de clients ETI moyens | B8: =B7/Hypothèses!C17 -> 39.242716 | C8: =C7/Hypothèses!D17 -> 58.695733
A9: Franchissement effectif (lecture du Trimestriel) | B9: EBITDA trimestriel positif à partir du T7 (an 2) ; EBITDA annuel positif an 3.
A11: Entonnoir commercial an 1 — d'où viennent les 15 clients
A12: Contrats visés an 1 | B12: =Hypothèses!B14 -> 15
A13: Pilotes nécessaires | B13: =B12/Hypothèses!B7 -> 25
A14: Démos nécessaires | B14: =B13/Hypothèses!B23 -> 62.5
A15: RDV nécessaires | B15: =B14/Hypothèses!B22 -> 125
A16: Comptes à travailler (sur 7 442 ETI) | B16: =B15/Hypothèses!B21 -> 500 | F16: ≈ 500 comptes ⇒ intenable pour une personne seule ⇒ l'AE recruté dès M4 est indispensable.
A18: Sensibilité — EBITDA an 3 (approximations documentées)
A19: Scénario central | B19: ='Compte de résultat'!D14 -> 1954184.7
A20: Ventes −30 % (marge brute ×0,7, charges fixes constantes) | B20: ='Compte de résultat'!D9*0.7+SUM('Compte de résultat'!D10:D13) -> 334793.43 | F20: Le projet reste bénéficiaire an 3 même à −30 % de ventes : c'est l'argument de robustesse.
A21: Prix −20 % (CA ×0,8, COGS constants) | B21: ='Compte de résultat'!D7*0.8+'Compte de résultat'!D8+SUM('Compte de résultat'!D10:D13) -> 608191.96
A22: Mix Patrimoine gelé à 20 % (prix moyen 9,40 €) | B22: ='Compte de résultat'!D7*(9.4/Hypothèses!D11)*0.8+SUM('Compte de résultat'!D10:D13) -> 1399211.7
A24: Besoin de financement — justification de la levée
A25: Besoin cumulé maximal hors levée (scénario central) | B25: =-MIN(Trimestriel!B44:M44) -> 917604.61
A26: Besoin en scénario prudent (−30 % de marge brute an 2) | B26: =B25+0.3*Trimestriel!O25 -> 1430623.5 | F26: Approximation : le retard de marge an 2 s'ajoute au besoin central.
A27: Levée sollicitée | B27: =Hypothèses!B66 -> 1500000
A28: Marge de sécurité sur le scénario prudent | B28: =IFERROR(B27/B26-1,"") -> 0.048493889
A29: Trésorerie minimale sur 3 ans (avec levée) | B29: =MIN(Trimestriel!B43:M43) -> 602395.39
